{
 "cells": [
  {
   "cell_type": "markdown",
   "id": "e1c3b444-064b-4639-983d-238b3da68ad9",
   "metadata": {},
   "source": [
    "# Imports"
   ]
  },
  {
   "cell_type": "code",
   "execution_count": 1,
   "id": "a6531aaa-2c26-40f5-8078-d754aceda153",
   "metadata": {
    "execution": {
     "iopub.execute_input": "2022-06-10T09:25:11.869216Z",
     "iopub.status.busy": "2022-06-10T09:25:11.868988Z",
     "iopub.status.idle": "2022-06-10T09:25:11.877868Z",
     "shell.execute_reply": "2022-06-10T09:25:11.877350Z",
     "shell.execute_reply.started": "2022-06-10T09:25:11.869167Z"
    },
    "tags": []
   },
   "outputs": [],
   "source": [
    "config = {\n",
    "    'dhdt': {\n",
    "        'depth': 3,\n",
    "        'learning_rate': 0.01,#1e-3,\n",
    "        \n",
    "        'initializer': 'he_normal', #GlorotUniform\n",
    "        'initializer_index': 'he_normal', #GlorotUniform        \n",
    "        \n",
    "        'loss': 'binary_crossentropy',#'mae',\n",
    "        'optimizer': 'adam',        \n",
    "        \n",
    "        'beta_1': 10,\n",
    "        'beta_2': 50,\n",
    "        \n",
    "        'squeeze_factor': 1,\n",
    "        \n",
    "        'batch_size': 512,\n",
    "        'epochs': 1_000,\n",
    "        'early_stopping_epochs': 50,\n",
    "    },\n",
    "    \n",
    "    \n",
    "    \n",
    "    'make_classification': {\n",
    "        'number_of_variables': 10,\n",
    "        'n_samples': 5_000,\n",
    "        'num_eval': 10,\n",
    "    },\n",
    "\n",
    "    'computation': {\n",
    "        'random_seed': 42,\n",
    "        'trials': 5,\n",
    "        'n_jobs': 50,\n",
    "        'verbosity': 0,\n",
    "    },\n",
    "}\n",
    "\n"
   ]
  },
  {
   "cell_type": "code",
   "execution_count": 2,
   "id": "b6ab8be2-1b4c-4370-a837-9176d15bea41",
   "metadata": {
    "execution": {
     "iopub.execute_input": "2022-06-10T09:25:11.878658Z",
     "iopub.status.busy": "2022-06-10T09:25:11.878544Z",
     "iopub.status.idle": "2022-06-10T09:25:17.775754Z",
     "shell.execute_reply": "2022-06-10T09:25:17.774923Z",
     "shell.execute_reply.started": "2022-06-10T09:25:11.878643Z"
    },
    "tags": []
   },
   "outputs": [],
   "source": [
    "import numpy as np\n",
    "\n",
    "import sklearn\n",
    "from sklearn.datasets import make_classification\n",
    "from sklearn.model_selection import train_test_split, ParameterGrid\n",
    "from sklearn.tree import DecisionTreeClassifier, plot_tree\n",
    "from sklearn.metrics import accuracy_score\n",
    "from sklearn.compose import ColumnTransformer\n",
    "from sklearn.preprocessing import OneHotEncoder, MinMaxScaler, LabelEncoder, OrdinalEncoder\n",
    "\n",
    "from livelossplot import PlotLosses\n",
    "\n",
    "import os\n",
    "from tqdm.notebook import tqdm\n",
    "from matplotlib import pyplot as plt\n",
    "\n",
    "from IPython.display import Image\n",
    "from IPython.display import display, clear_output\n",
    "\n",
    "import pandas as pd\n",
    "\n",
    "os.environ['CUDA_VISIBLE_DEVICES'] = ''\n",
    "os.environ['TF_FORCE_GPU_ALLOW_GROWTH'] = '' #'true'\n",
    "\n",
    "import warnings\n",
    "warnings.filterwarnings('ignore')\n",
    "os.environ['TF_CPP_MIN_LOG_LEVEL'] = '3' \n",
    "import logging\n",
    "\n",
    "import tensorflow as tf\n",
    "import tensorflow_addons as tfa\n",
    "\n",
    "tf.get_logger().setLevel('ERROR')\n",
    "tf.autograph.set_verbosity(3)\n",
    "\n",
    "np.seterr(all=\"ignore\")\n",
    "\n",
    "from keras import backend as K\n",
    "from keras.utils.generic_utils import get_custom_objects\n",
    "\n",
    "\n",
    "import seaborn as sns\n",
    "sns.set_style(\"darkgrid\")\n",
    "\n",
    "import time\n",
    "import random\n",
    "\n",
    "from utilities.utilities import *\n",
    "from utilities.DHDT import *\n",
    "\n",
    "from joblib import Parallel, delayed\n",
    "\n",
    "from itertools import product\n",
    "from collections.abc import Iterable\n",
    "\n",
    "from copy import deepcopy"
   ]
  },
  {
   "cell_type": "markdown",
   "id": "f2397843-32d2-4579-b197-0686f4a99b54",
   "metadata": {},
   "source": [
    "# Evaluation"
   ]
  },
  {
   "cell_type": "markdown",
   "id": "fa3e7da9-12bb-467f-919f-4fd510ce6463",
   "metadata": {},
   "source": [
    "## make_classification"
   ]
  },
  {
   "cell_type": "code",
   "execution_count": 3,
   "id": "9e8a1baf-79d0-4959-8376-fc6a5446a229",
   "metadata": {
    "execution": {
     "iopub.execute_input": "2022-06-10T09:25:17.778088Z",
     "iopub.status.busy": "2022-06-10T09:25:17.777945Z",
     "iopub.status.idle": "2022-06-10T09:25:17.795361Z",
     "shell.execute_reply": "2022-06-10T09:25:17.794635Z",
     "shell.execute_reply.started": "2022-06-10T09:25:17.778067Z"
    },
    "tags": []
   },
   "outputs": [],
   "source": [
    "if False:\n",
    "    metrics = ['accuracy', 'f1']\n",
    "    \n",
    "    config_test = deepcopy(config)\n",
    "    config_test['make_classification']['n_samples'] = 10_000\n",
    "    config_test['dhdt']['epochs'] = 100\n",
    "\n",
    "    dataset_dict = {}\n",
    "    model_dict = {}\n",
    "\n",
    "    scores_dict = {'sklearn': {},\n",
    "                   'DHDT': {}}\n",
    "\n",
    "    dataset_dict = get_preprocessed_dataset('make_classification',\n",
    "                                            random_seed=config_test['computation']['random_seed'],\n",
    "                                            config=config_test['make_classification'],\n",
    "                                            verbosity=1)\n",
    "\n",
    "    model_dict['sklearn'] = DecisionTreeClassifier(max_depth=3, \n",
    "                                                   random_state=config_test['computation']['random_seed'])\n",
    "\n",
    "    model_dict['sklearn'].fit(dataset_dict['X_train'], \n",
    "                              dataset_dict['y_train'])\n",
    "\n",
    "\n",
    "\n",
    "    model_dict['DHDT'] = DHDT(dataset_dict['X_train'].shape[1],\n",
    "\n",
    "                                depth = config_test['dhdt']['depth'],\n",
    "\n",
    "                                learning_rate = config_test['dhdt']['learning_rate'],\n",
    "                                optimizer = config_test['dhdt']['optimizer'],\n",
    "\n",
    "                                initializer = config_test['dhdt']['initializer'],\n",
    "                                initializer_index = config_test['dhdt']['initializer_index'],                              \n",
    "                              \n",
    "                                beta_1 = config_test['dhdt']['beta_1'],\n",
    "                                beta_2 = config_test['dhdt']['beta_2'],\n",
    "\n",
    "                                squeeze_factor = config_test['dhdt']['squeeze_factor'],\n",
    "\n",
    "                                loss = config_test['dhdt']['loss'],#'mae',\n",
    "\n",
    "                                random_seed = config_test['computation']['random_seed'],\n",
    "                                verbosity = 2)        \n",
    "\n",
    "\n",
    "    scores_dict['history'] = model_dict['DHDT'].fit(dataset_dict['X_train'], \n",
    "                                                  dataset_dict['y_train'], \n",
    "                                                  batch_size=config_test['dhdt']['batch_size'], \n",
    "                                                  epochs=config_test['dhdt']['epochs'], \n",
    "                                                  early_stopping_epochs=config_test['dhdt']['early_stopping_epochs'], \n",
    "                                                  valid_data=(dataset_dict['X_valid'], dataset_dict['y_valid']))\n",
    "\n",
    "\n",
    "\n",
    "    dataset_dict['y_test_dhdt'] = model_dict['DHDT'].predict(dataset_dict['X_test'])\n",
    "    dataset_dict['y_valid_dhdt'] = model_dict['DHDT'].predict(dataset_dict['X_valid'])\n",
    "\n",
    "    dataset_dict['y_test_sklearn'] = model_dict['sklearn'].predict(dataset_dict['X_test'])\n",
    "    dataset_dict['y_valid_sklearn'] = model_dict['sklearn'].predict(dataset_dict['X_valid'])     \n",
    "    \n",
    "    for metric in metrics:\n",
    "        \n",
    "        if metric in ['accuracy', 'f1']:\n",
    "            y_test_dhdt = np.round(dataset_dict['y_test_dhdt'])\n",
    "            y_valid_dhdt = np.round(dataset_dict['y_valid_dhdt'])\n",
    "            y_test_sklearn = np.round(dataset_dict['y_test_sklearn'])\n",
    "            y_valid_sklearn = np.round(dataset_dict['y_valid_sklearn'])         \n",
    "        else:\n",
    "            y_test_dhdt = dataset_dict['y_test_dhdt']\n",
    "            y_valid_dhdt = dataset_dict['y_valid_dhdt']\n",
    "            y_test_sklearn = dataset_dict['y_test_sklearn']\n",
    "            y_valid_sklearn =    dataset_dict['y_valid_sklearn']                \n",
    "        \n",
    "        scores_dict['sklearn'][metric + '_test'] = sklearn.metrics.get_scorer(metric)._score_func(dataset_dict['y_test'], y_test_sklearn)\n",
    "        scores_dict['DHDT'][metric + '_test'] = sklearn.metrics.get_scorer(metric)._score_func(dataset_dict['y_test'], y_test_dhdt)\n",
    "\n",
    "        scores_dict['sklearn'][metric + '_valid'] = sklearn.metrics.get_scorer(metric)._score_func(dataset_dict['y_valid'], y_valid_sklearn)   \n",
    "        scores_dict['DHDT'][metric + '_valid'] = sklearn.metrics.get_scorer(metric)._score_func(dataset_dict['y_valid'], y_valid_dhdt)\n"
   ]
  },
  {
   "cell_type": "code",
   "execution_count": 4,
   "id": "54a13b2a-ca9d-44de-9a52-b8ca61808093",
   "metadata": {
    "execution": {
     "iopub.execute_input": "2022-06-10T09:25:17.796747Z",
     "iopub.status.busy": "2022-06-10T09:25:17.796448Z",
     "iopub.status.idle": "2022-06-10T09:25:17.840650Z",
     "shell.execute_reply": "2022-06-10T09:25:17.839946Z",
     "shell.execute_reply.started": "2022-06-10T09:25:17.796714Z"
    },
    "tags": []
   },
   "outputs": [],
   "source": [
    "if False:\n",
    "    parallel_eval_synthetic = Parallel(n_jobs=config['computation']['n_jobs'], verbose=3, backend='loky') #loky #sequential multiprocessing\n",
    "    evaluation_results_synthetic = parallel_eval_synthetic(delayed(evaluate_synthetic_parallel)(index = index,\n",
    "                                                                                                random_seed_data = config['computation']['random_seed']+index,\n",
    "                                                                                                random_seed_model = config['computation']['random_seed'],#+random_seed_model,\n",
    "                                                                                                config = config,\n",
    "                                                                                                verbosity = -1) for index in range(config['make_classification']['num_eval']))\n",
    "\n",
    "    for i, synthetic_result in enumerate(evaluation_results_synthetic):\n",
    "        if i == 0:\n",
    "            model_dict_synthetic = synthetic_result[0]\n",
    "            scores_dict_synthetic = synthetic_result[1]\n",
    "            dataset_dict_synthetic = synthetic_result[2]\n",
    "        else: \n",
    "            model_dict_synthetic = mergeDict(model_dict_synthetic, synthetic_result[0])\n",
    "            scores_dict_synthetic = mergeDict(scores_dict_synthetic, synthetic_result[1])\n",
    "            dataset_dict_synthetic = mergeDict(dataset_dict_synthetic, synthetic_result[2])        \n",
    "    \n",
    "    metric_identifer = '_test'\n",
    "    metrics = ['accuracy', 'f1']\n",
    "    index = [i for i in range(config['make_classification']['num_eval'])]\n",
    "    columns = flatten_list([[[approach + ' ' + metric + '_mean', approach + ' ' + metric + '_max', approach + ' ' + metric + '_std'] for metric in metrics] for approach in ['DHDT', 'sklearn']])\n",
    "\n",
    "\n",
    "    results_DHDT = None\n",
    "    results_sklearn = None\n",
    "    for metric in metrics:\n",
    "        scores_DHDT = [scores_dict_synthetic[i]['DHDT'][metric + metric_identifer] for i in range(config['make_classification']['num_eval'])]\n",
    "\n",
    "        scores_sklearn = [scores_dict_synthetic[i]['sklearn'][metric + metric_identifer] for i in range(config['make_classification']['num_eval'])]\n",
    "\n",
    "        scores_DHDT_mean = np.mean(scores_DHDT, axis=1) if config['computation']['trials'] > 1 else scores_DHDT\n",
    "        scores_sklearn_mean = np.mean(scores_sklearn, axis=1) if config['computation']['trials'] > 1 else scores_sklearn\n",
    "\n",
    "        scores_DHDT_max = np.max(scores_DHDT, axis=1) if config['computation']['trials'] > 1 else scores_DHDT\n",
    "        scores_sklearn_max = np.max(scores_sklearn, axis=1) if config['computation']['trials'] > 1 else scores_sklearn\n",
    "\n",
    "        scores_DHDT_std = np.std(scores_DHDT, axis=1) if config['computation']['trials'] > 1 else np.array([0.0] * config['computation']['trials'])\n",
    "        scores_sklearn_std = np.std(scores_sklearn, axis=1) if config['computation']['trials'] > 1 else np.array([0.0] * config['computation']['trials'])\n",
    "\n",
    "        results_DHDT_by_metric = np.vstack([scores_DHDT_mean, scores_DHDT_max, scores_DHDT_std])\n",
    "        results_sklearn_by_metric = np.vstack([scores_sklearn_mean, scores_sklearn_max, scores_sklearn_std])\n",
    "\n",
    "        if results_DHDT is None and results_sklearn is None:\n",
    "            results_DHDT = results_DHDT_by_metric\n",
    "            results_sklearn = results_sklearn_by_metric\n",
    "        else:\n",
    "            results_DHDT = np.vstack([results_DHDT, results_DHDT_by_metric])\n",
    "            results_sklearn = np.vstack([results_sklearn, results_sklearn_by_metric])\n",
    "\n",
    "    scores_dataframe_synthetic = pd.DataFrame(data=np.vstack([results_DHDT, results_sklearn]).T, index = index, columns = columns)    \n",
    "        \n",
    "    index = [index_name.split(' ')[1] for index_name in scores_dataframe_synthetic.mean()[scores_dataframe_synthetic.shape[1]//2:].index]\n",
    "    mean_result_dataframe_synthetic = np.round(pd.DataFrame(data=np.vstack([scores_dataframe_synthetic.mean()[:scores_dataframe_synthetic.shape[1]//2], scores_dataframe_synthetic.mean()[scores_dataframe_synthetic.shape[1]//2:]]).T, index=index, columns=['DHDT', 'sklearn']), 3)\n",
    "\n",
    "        \n",
    "    display(scores_dataframe_synthetic.head(5))\n",
    "    display(scores_dataframe_synthetic[scores_dataframe_synthetic.columns[0::3]].iloc[:,[0,2,1,3]].head(5))\n",
    "    display(scores_dataframe_synthetic[scores_dataframe_synthetic.columns[1::3]].iloc[:,[0,2,1,3]].head(5))\n",
    "    display(mean_result_dataframe_synthetic)\n",
    "    "
   ]
  },
  {
   "cell_type": "markdown",
   "id": "f856c6c9-368b-4b75-b0d8-6e7a28e4267c",
   "metadata": {},
   "source": [
    "## Real-World Eval"
   ]
  },
  {
   "cell_type": "code",
   "execution_count": 5,
   "id": "6cb9eca0-b6be-4389-960f-857e68e6b197",
   "metadata": {
    "execution": {
     "iopub.execute_input": "2022-06-10T09:25:17.842077Z",
     "iopub.status.busy": "2022-06-10T09:25:17.841788Z",
     "iopub.status.idle": "2022-06-10T09:25:17.948425Z",
     "shell.execute_reply": "2022-06-10T09:25:17.947691Z",
     "shell.execute_reply.started": "2022-06-10T09:25:17.842047Z"
    },
    "tags": []
   },
   "outputs": [],
   "source": [
    "if False:\n",
    "\n",
    "    identifier_list = [\n",
    "                        'Adult',#: 32,\n",
    "                        'Bank Marketing',#: 32,\n",
    "                        'Loan Credit',#: 32,\n",
    "\n",
    "                        'Credit Card',#: 23, \n",
    "                        'Car',#: 21,\n",
    "\n",
    "\n",
    "                        'Absenteeism',#: 15,\n",
    "                        'Loan House',#: 15,\n",
    "                        'Cervical Cancer',#: 15,\n",
    "\n",
    "                        'Heart Disease',#: 13,           \n",
    "\n",
    "                        'Titanic',#: 10,\n",
    "                        'Medical Insurance',#: 10,\n",
    "                        'Wisconsin Breast Cancer Original',#: 10,\n",
    "                        'Wisconsin Diagnostic Breast Cancer',#: 10,\n",
    "                        'Wisconsin Prognostic Breast Cancer',#: 10,\n",
    "                        'Abalone',#: 10,\n",
    "\n",
    "                        'Habermans Survival',#: 3, \n",
    "                      ]\n",
    "    \n",
    "    parallel_eval_real_world = Parallel(n_jobs=config['computation']['n_jobs'], verbose=3, backend='loky') #loky #sequential multiprocessing\n",
    "    evaluation_results_real_world = parallel_eval_real_world(delayed(evaluate_real_world_parallel)(identifier_list=identifier_list, \n",
    "                                                                                                   random_seed_model=config['computation']['random_seed']+i,\n",
    "                                                                                                   config = config,\n",
    "                                                                                                   verbosity = -1) for i in range(config['computation']['trials']))\n",
    "\n",
    "\n",
    "    for i, real_world_result in enumerate(evaluation_results_real_world):\n",
    "        if i == 0:\n",
    "            model_dict_real_world = real_world_result[0]\n",
    "            scores_dict_real_world = real_world_result[1]\n",
    "            dataset_dict_real_world = real_world_result[2]\n",
    "        else: \n",
    "            model_dict_real_world = mergeDict(model_dict_real_world, real_world_result[0])\n",
    "            scores_dict_real_world = mergeDict(scores_dict_real_world, real_world_result[1])\n",
    "            dataset_dict_real_world = mergeDict(dataset_dict_real_world, real_world_result[2])    \n",
    "\n",
    "    metric_identifer = '_test'\n",
    "    metrics = ['accuracy', 'f1']\n",
    "    index = identifier_list\n",
    "    columns = flatten_list([[[approach + ' ' + metric + '_mean', approach + ' ' + metric + '_max', approach + ' ' + metric + '_std'] for metric in metrics] for approach in ['DHDT', 'sklearn']])\n",
    "\n",
    "\n",
    "    results_DHDT = None\n",
    "    results_sklearn = None\n",
    "    for metric in metrics:\n",
    "        scores_DHDT = [scores_dict_real_world[identifier]['DHDT'][metric + metric_identifer] for identifier in identifier_list]\n",
    "\n",
    "        scores_sklearn = [scores_dict_real_world[identifier]['sklearn'][metric + metric_identifer] for identifier in identifier_list]    \n",
    "\n",
    "        scores_DHDT_mean = np.mean(scores_DHDT, axis=1) if config['computation']['trials'] > 1 else scores_DHDT\n",
    "        scores_sklearn_mean = np.mean(scores_sklearn, axis=1) if config['computation']['trials'] > 1 else scores_sklearn\n",
    "\n",
    "        scores_DHDT_max = np.max(scores_DHDT, axis=1) if config['computation']['trials'] > 1 else scores_DHDT\n",
    "        scores_sklearn_max = np.max(scores_sklearn, axis=1) if config['computation']['trials'] > 1 else scores_sklearn\n",
    "\n",
    "        scores_DHDT_std = np.std(scores_DHDT, axis=1) if config['computation']['trials'] > 1 else np.array([0.0] * config['computation']['trials'])\n",
    "        scores_sklearn_std = np.std(scores_sklearn, axis=1) if config['computation']['trials'] > 1 else np.array([0.0] * config['computation']['trials'])\n",
    "\n",
    "        results_DHDT_by_metric = np.vstack([scores_DHDT_mean, scores_DHDT_max, scores_DHDT_std])\n",
    "        results_sklearn_by_metric = np.vstack([scores_sklearn_mean, scores_sklearn_max, scores_sklearn_std])\n",
    "\n",
    "        if results_DHDT is None and results_sklearn is None:\n",
    "            results_DHDT = results_DHDT_by_metric\n",
    "            results_sklearn = results_sklearn_by_metric\n",
    "        else:\n",
    "            results_DHDT = np.vstack([results_DHDT, results_DHDT_by_metric])\n",
    "            results_sklearn = np.vstack([results_sklearn, results_sklearn_by_metric])\n",
    "            \n",
    "    scores_dataframe_real_world = pd.DataFrame(data=np.vstack([results_DHDT, results_sklearn]).T, index = index, columns = columns)\n",
    "            \n",
    "    index = [index_name.split(' ')[1] for index_name in scores_dataframe_real_world.mean()[scores_dataframe_real_world.shape[1]//2:].index]\n",
    "    mean_result_dataframe_real_world = np.round(pd.DataFrame(data=np.vstack([scores_dataframe_real_world.mean()[:scores_dataframe_real_world.shape[1]//2], scores_dataframe_real_world.mean()[scores_dataframe_real_world.shape[1]//2:]]).T, index=index, columns=['DHDT', 'sklearn']), 3)\n",
    "                \n",
    "    display(scores_dataframe_real_world)\n",
    "    display(scores_dataframe_real_world[scores_dataframe_real_world.columns[0::3]].iloc[:,[0,2,1,3]])    \n",
    "    display(scores_dataframe_real_world[scores_dataframe_real_world.columns[1::3]].iloc[:,[0,2,1,3]])    \n",
    "\n",
    "    display(mean_result_dataframe_real_world)\n",
    "    \n"
   ]
  },
  {
   "cell_type": "code",
   "execution_count": 6,
   "id": "38c55370-5fa9-4f3c-a1a8-be597467f808",
   "metadata": {
    "execution": {
     "iopub.execute_input": "2022-06-10T09:25:17.949751Z",
     "iopub.status.busy": "2022-06-10T09:25:17.949461Z",
     "iopub.status.idle": "2022-06-10T09:25:17.986280Z",
     "shell.execute_reply": "2022-06-10T09:25:17.985604Z",
     "shell.execute_reply.started": "2022-06-10T09:25:17.949720Z"
    },
    "tags": []
   },
   "outputs": [],
   "source": [
    "if False:\n",
    "    plot_index = 0\n",
    "    \n",
    "    identifier = identifier_list[0]#\"Absenteeism\"\n",
    "    plt.figure(figsize=(15,8))\n",
    "    image = model_dict_real_world[identifier]['DHDT'][plot_index].plot(normalizer_list=dataset_dict_real_world[identifier]['normalizer_list'])\n",
    "    display(image)\n",
    "\n",
    "    plt.figure(figsize=(15,8))\n",
    "    plot_tree(model_dict_real_world[identifier]['sklearn'][plot_index], fontsize=10) \n",
    "    plt.show()"
   ]
  },
  {
   "cell_type": "code",
   "execution_count": null,
   "id": "196fbd88-44c9-4d7f-b58d-def1eeb6d434",
   "metadata": {
    "tags": []
   },
   "outputs": [],
   "source": []
  },
  {
   "cell_type": "markdown",
   "id": "84e73582-0f9e-4522-9a94-dc59f4e566e9",
   "metadata": {},
   "source": [
    "# Hyperparameter Optimization"
   ]
  },
  {
   "cell_type": "code",
   "execution_count": 7,
   "id": "09315b63-50a1-4b2c-bfa9-d7b6d961de34",
   "metadata": {
    "execution": {
     "iopub.execute_input": "2022-06-10T09:25:17.987607Z",
     "iopub.status.busy": "2022-06-10T09:25:17.987300Z",
     "iopub.status.idle": "2022-06-10T09:25:18.036049Z",
     "shell.execute_reply": "2022-06-10T09:25:18.035323Z",
     "shell.execute_reply.started": "2022-06-10T09:25:17.987557Z"
    },
    "tags": []
   },
   "outputs": [],
   "source": [
    "parameter_dict = {\n",
    "        #'depth': [3],\n",
    "        #'learning_rate': [0.05, 0.01, 0.005, 0.001, 0.0005], #[0.1, 0.05, 0.01, 0.005, 0.001, 0.0005, 0.0001],\n",
    "        \n",
    "        #'loss': ['binary_crossentropy'], #['binary_crossentropy', 'rmse'], #'mae',\n",
    "        #'optimizer': ['adam', 'sgd'], #['adam', 'sgd'],        \n",
    "        \n",
    "        'initializer': ['GlorotUniform', 'GlorotNormal', 'HeUniform', 'HeNormal', 'LecunUniform', 'LecunNormal', 'RandomNormal', 'RandomUniform'], #RandomNormal, RandomUniform\n",
    "        'initializer_index': ['GlorotUniform', 'GlorotNormal', 'HeUniform', 'HeNormal', 'LecunUniform', 'LecunNormal', 'RandomNormal', 'RandomUniform', 'zeros', 'ones'], #RandomNormal, RandomUniform\n",
    "\n",
    "        #'beta_1': [10, 50], #[10, 50, 100],\n",
    "        #'beta_2': [10, 50], #[10, 50, 100],\n",
    "        \n",
    "        #'squeeze_factor': [0.2, 0.5, 1, 2, 5], #[0.2, 0.5, 1, 2, 5],    \n",
    "}\n",
    "\n",
    "parameter_grid = ParameterGrid(parameter_dict)"
   ]
  },
  {
   "cell_type": "code",
   "execution_count": null,
   "id": "952be342-9751-474b-8780-f185b3f9c29d",
   "metadata": {
    "collapsed": true,
    "execution": {
     "iopub.execute_input": "2022-06-10T13:02:27.492727Z",
     "iopub.status.busy": "2022-06-10T13:02:27.492491Z",
     "iopub.status.idle": "2022-06-10T13:02:43.327261Z"
    },
    "jupyter": {
     "outputs_hidden": true
    },
    "tags": []
   },
   "outputs": [
    {
     "name": "stderr",
     "output_type": "stream",
     "text": [
      "[Parallel(n_jobs=50)]: Using backend LokyBackend with 50 concurrent workers.\n",
      "[Parallel(n_jobs=50)]: Done   8 out of  80 | elapsed:    2.2s remaining:   20.1s\n",
      "[Parallel(n_jobs=50)]: Done  35 out of  80 | elapsed:    2.2s remaining:    2.9s\n",
      "[Parallel(n_jobs=50)]: Done  62 out of  80 | elapsed:    2.2s remaining:    0.6s\n",
      "Traceback (most recent call last):\n",
      "  File \"<frozen importlib._bootstrap_external>\", line 93, in _path_is_mode_type\n",
      "  File \"<frozen importlib._bootstrap_external>\", line 87, in _path_stat\n",
      "FileNotFoundError: [Errno 2] No such file or directory: '/home/smarton/anaconda3/envs/XAI/lib/python3.8/urllib/__init__.cpython-38-x86_64-linux-gnu.so'\n",
      "\n",
      "During handling of the above exception, another exception occurred:\n",
      "\n",
      "Traceback (most recent call last):\n",
      "  File \"/home/smarton/anaconda3/envs/XAI/lib/python3.8/runpy.py\", line 183, in _run_module_as_main\n",
      "    mod_name, mod_spec, code = _get_module_details(mod_name, _Error)\n",
      "  File \"/home/smarton/anaconda3/envs/XAI/lib/python3.8/runpy.py\", line 109, in _get_module_details\n",
      "    __import__(pkg_name)\n",
      "  File \"/home/smarton/anaconda3/envs/XAI/lib/python3.8/site-packages/joblib/__init__.py\", line 113, in <module>\n",
      "    from .memory import Memory, MemorizedResult, register_store_backend\n",
      "  File \"/home/smarton/anaconda3/envs/XAI/lib/python3.8/site-packages/joblib/memory.py\", line 15, in <module>\n",
      "    import pathlib\n",
      "  File \"/home/smarton/anaconda3/envs/XAI/lib/python3.8/pathlib.py\", line 13, in <module>\n",
      "    from urllib.parse import quote_from_bytes as urlquote_from_bytes\n",
      "  File \"<frozen importlib._bootstrap>\", line 991, in _find_and_load\n",
      "  File \"<frozen importlib._bootstrap>\", line 971, in _find_and_load_unlocked\n",
      "  File \"<frozen importlib._bootstrap>\", line 914, in _find_spec\n",
      "  File \"<frozen importlib._bootstrap_external>\", line 1342, in find_spec\n",
      "  File \"<frozen importlib._bootstrap_external>\", line 1314, in _get_spec\n",
      "  File \"<frozen importlib._bootstrap_external>\", line 1458, in find_spec\n",
      "  File \"<frozen importlib._bootstrap_external>\", line 101, in _path_isfile\n",
      "  File \"<frozen importlib._bootstrap_external>\", line 93, in _path_is_mode_type\n",
      "KeyboardInterrupt\n",
      "Traceback (most recent call last):\n",
      "  File \"<frozen importlib._bootstrap_external>\", line 93, in _path_is_mode_type\n",
      "  File \"<frozen importlib._bootstrap_external>\", line 87, in _path_stat\n",
      "FileNotFoundError: [Errno 2] No such file or directory: '/home/smarton/anaconda3/envs/XAI/lib/python3.8/urllib/__init__.cpython-38-x86_64-linux-gnu.so'\n",
      "\n",
      "During handling of the above exception, another exception occurred:\n",
      "\n",
      "Traceback (most recent call last):\n",
      "  File \"/home/smarton/anaconda3/envs/XAI/lib/python3.8/runpy.py\", line 183, in _run_module_as_main\n",
      "    mod_name, mod_spec, code = _get_module_details(mod_name, _Error)\n",
      "  File \"/home/smarton/anaconda3/envs/XAI/lib/python3.8/runpy.py\", line 109, in _get_module_details\n",
      "    __import__(pkg_name)\n",
      "  File \"/home/smarton/anaconda3/envs/XAI/lib/python3.8/site-packages/joblib/__init__.py\", line 113, in <module>\n",
      "    from .memory import Memory, MemorizedResult, register_store_backend\n",
      "  File \"/home/smarton/anaconda3/envs/XAI/lib/python3.8/site-packages/joblib/memory.py\", line 15, in <module>\n",
      "    import pathlib\n",
      "  File \"/home/smarton/anaconda3/envs/XAI/lib/python3.8/pathlib.py\", line 13, in <module>\n",
      "    from urllib.parse import quote_from_bytes as urlquote_from_bytes\n",
      "  File \"<frozen importlib._bootstrap>\", line 991, in _find_and_load\n",
      "  File \"<frozen importlib._bootstrap>\", line 971, in _find_and_load_unlocked\n",
      "  File \"<frozen importlib._bootstrap>\", line 914, in _find_spec\n",
      "  File \"<frozen importlib._bootstrap_external>\", line 1342, in find_spec\n",
      "  File \"<frozen importlib._bootstrap_external>\", line 1314, in _get_spec\n",
      "  File \"<frozen importlib._bootstrap_external>\", line 1458, in find_spec\n",
      "  File \"<frozen importlib._bootstrap_external>\", line 101, in _path_isfile\n",
      "  File \"<frozen importlib._bootstrap_external>\", line 93, in _path_is_mode_type\n",
      "KeyboardInterrupt\n",
      "Traceback (most recent call last):\n",
      "  File \"<frozen importlib._bootstrap_external>\", line 93, in _path_is_mode_type\n",
      "  File \"<frozen importlib._bootstrap_external>\", line 87, in _path_stat\n",
      "FileNotFoundError: [Errno 2] No such file or directory: '/home/smarton/anaconda3/envs/XAI/lib/python3.8/urllib/__init__.cpython-38-x86_64-linux-gnu.so'\n",
      "\n",
      "During handling of the above exception, another exception occurred:\n",
      "\n",
      "Traceback (most recent call last):\n",
      "  File \"/home/smarton/anaconda3/envs/XAI/lib/python3.8/runpy.py\", line 183, in _run_module_as_main\n",
      "    mod_name, mod_spec, code = _get_module_details(mod_name, _Error)\n",
      "  File \"/home/smarton/anaconda3/envs/XAI/lib/python3.8/runpy.py\", line 109, in _get_module_details\n",
      "    __import__(pkg_name)\n",
      "  File \"/home/smarton/anaconda3/envs/XAI/lib/python3.8/site-packages/joblib/__init__.py\", line 113, in <module>\n",
      "    from .memory import Memory, MemorizedResult, register_store_backend\n",
      "  File \"/home/smarton/anaconda3/envs/XAI/lib/python3.8/site-packages/joblib/memory.py\", line 15, in <module>\n",
      "    import pathlib\n",
      "  File \"/home/smarton/anaconda3/envs/XAI/lib/python3.8/pathlib.py\", line 13, in <module>\n",
      "    from urllib.parse import quote_from_bytes as urlquote_from_bytes\n",
      "  File \"<frozen importlib._bootstrap>\", line 991, in _find_and_load\n",
      "  File \"<frozen importlib._bootstrap>\", line 971, in _find_and_load_unlocked\n",
      "  File \"<frozen importlib._bootstrap>\", line 914, in _find_spec\n",
      "  File \"<frozen importlib._bootstrap_external>\", line 1342, in find_spec\n",
      "  File \"<frozen importlib._bootstrap_external>\", line 1314, in _get_spec\n",
      "  File \"<frozen importlib._bootstrap_external>\", line 1458, in find_spec\n",
      "  File \"<frozen importlib._bootstrap_external>\", line 101, in _path_isfile\n",
      "  File \"<frozen importlib._bootstrap_external>\", line 93, in _path_is_mode_type\n",
      "KeyboardInterrupt\n",
      "Traceback (most recent call last):\n",
      "  File \"<frozen importlib._bootstrap_external>\", line 93, in _path_is_mode_type\n",
      "  File \"<frozen importlib._bootstrap_external>\", line 87, in _path_stat\n",
      "FileNotFoundError: [Errno 2] No such file or directory: '/home/smarton/anaconda3/envs/XAI/lib/python3.8/urllib/__init__.cpython-38-x86_64-linux-gnu.so'\n",
      "\n",
      "During handling of the above exception, another exception occurred:\n",
      "\n",
      "Traceback (most recent call last):\n",
      "  File \"/home/smarton/anaconda3/envs/XAI/lib/python3.8/runpy.py\", line 183, in _run_module_as_main\n",
      "    mod_name, mod_spec, code = _get_module_details(mod_name, _Error)\n",
      "  File \"/home/smarton/anaconda3/envs/XAI/lib/python3.8/runpy.py\", line 109, in _get_module_details\n",
      "    __import__(pkg_name)\n",
      "  File \"/home/smarton/anaconda3/envs/XAI/lib/python3.8/site-packages/joblib/__init__.py\", line 113, in <module>\n",
      "    from .memory import Memory, MemorizedResult, register_store_backend\n",
      "  File \"/home/smarton/anaconda3/envs/XAI/lib/python3.8/site-packages/joblib/memory.py\", line 15, in <module>\n",
      "    import pathlib\n",
      "  File \"/home/smarton/anaconda3/envs/XAI/lib/python3.8/pathlib.py\", line 13, in <module>\n",
      "    from urllib.parse import quote_from_bytes as urlquote_from_bytes\n",
      "  File \"<frozen importlib._bootstrap>\", line 991, in _find_and_load\n",
      "  File \"<frozen importlib._bootstrap>\", line 971, in _find_and_load_unlocked\n",
      "  File \"<frozen importlib._bootstrap>\", line 914, in _find_spec\n",
      "  File \"<frozen importlib._bootstrap_external>\", line 1342, in find_spec\n",
      "  File \"<frozen importlib._bootstrap_external>\", line 1314, in _get_spec\n",
      "  File \"<frozen importlib._bootstrap_external>\", line 1458, in find_spec\n",
      "  File \"<frozen importlib._bootstrap_external>\", line 101, in _path_isfile\n",
      "  File \"<frozen importlib._bootstrap_external>\", line 93, in _path_is_mode_type\n",
      "KeyboardInterrupt\n",
      "Traceback (most recent call last):\n",
      "  File \"<frozen importlib._bootstrap_external>\", line 93, in _path_is_mode_type\n",
      "  File \"<frozen importlib._bootstrap_external>\", line 87, in _path_stat\n",
      "FileNotFoundError: [Errno 2] No such file or directory: '/home/smarton/anaconda3/envs/XAI/lib/python3.8/urllib/__init__.cpython-38-x86_64-linux-gnu.so'\n",
      "\n",
      "During handling of the above exception, another exception occurred:\n",
      "\n",
      "Traceback (most recent call last):\n",
      "  File \"/home/smarton/anaconda3/envs/XAI/lib/python3.8/runpy.py\", line 183, in _run_module_as_main\n",
      "    mod_name, mod_spec, code = _get_module_details(mod_name, _Error)\n",
      "  File \"/home/smarton/anaconda3/envs/XAI/lib/python3.8/runpy.py\", line 109, in _get_module_details\n",
      "    __import__(pkg_name)\n",
      "  File \"/home/smarton/anaconda3/envs/XAI/lib/python3.8/site-packages/joblib/__init__.py\", line 113, in <module>\n",
      "    from .memory import Memory, MemorizedResult, register_store_backend\n",
      "  File \"/home/smarton/anaconda3/envs/XAI/lib/python3.8/site-packages/joblib/memory.py\", line 15, in <module>\n",
      "    import pathlib\n",
      "  File \"/home/smarton/anaconda3/envs/XAI/lib/python3.8/pathlib.py\", line 13, in <module>\n",
      "    from urllib.parse import quote_from_bytes as urlquote_from_bytes\n",
      "  File \"<frozen importlib._bootstrap>\", line 991, in _find_and_load\n",
      "  File \"<frozen importlib._bootstrap>\", line 971, in _find_and_load_unlocked\n",
      "  File \"<frozen importlib._bootstrap>\", line 914, in _find_spec\n",
      "  File \"<frozen importlib._bootstrap_external>\", line 1342, in find_spec\n",
      "  File \"<frozen importlib._bootstrap_external>\", line 1314, in _get_spec\n",
      "  File \"<frozen importlib._bootstrap_external>\", line 1458, in find_spec\n",
      "  File \"<frozen importlib._bootstrap_external>\", line 101, in _path_isfile\n",
      "  File \"<frozen importlib._bootstrap_external>\", line 93, in _path_is_mode_type\n",
      "KeyboardInterrupt\n",
      "Traceback (most recent call last):\n",
      "  File \"<frozen importlib._bootstrap_external>\", line 93, in _path_is_mode_type\n",
      "  File \"<frozen importlib._bootstrap_external>\", line 87, in _path_stat\n",
      "FileNotFoundError: [Errno 2] No such file or directory: '/home/smarton/anaconda3/envs/XAI/lib/python3.8/urllib/__init__.cpython-38-x86_64-linux-gnu.so'\n",
      "\n",
      "During handling of the above exception, another exception occurred:\n",
      "\n",
      "Traceback (most recent call last):\n",
      "  File \"/home/smarton/anaconda3/envs/XAI/lib/python3.8/runpy.py\", line 183, in _run_module_as_main\n",
      "    mod_name, mod_spec, code = _get_module_details(mod_name, _Error)\n",
      "  File \"/home/smarton/anaconda3/envs/XAI/lib/python3.8/runpy.py\", line 109, in _get_module_details\n",
      "    __import__(pkg_name)\n",
      "  File \"/home/smarton/anaconda3/envs/XAI/lib/python3.8/site-packages/joblib/__init__.py\", line 113, in <module>\n",
      "    from .memory import Memory, MemorizedResult, register_store_backend\n",
      "  File \"/home/smarton/anaconda3/envs/XAI/lib/python3.8/site-packages/joblib/memory.py\", line 15, in <module>\n",
      "    import pathlib\n",
      "  File \"/home/smarton/anaconda3/envs/XAI/lib/python3.8/pathlib.py\", line 13, in <module>\n",
      "    from urllib.parse import quote_from_bytes as urlquote_from_bytes\n",
      "  File \"<frozen importlib._bootstrap>\", line 991, in _find_and_load\n",
      "  File \"<frozen importlib._bootstrap>\", line 971, in _find_and_load_unlocked\n",
      "  File \"<frozen importlib._bootstrap>\", line 914, in _find_spec\n",
      "  File \"<frozen importlib._bootstrap_external>\", line 1342, in find_spec\n",
      "  File \"<frozen importlib._bootstrap_external>\", line 1314, in _get_spec\n",
      "  File \"<frozen importlib._bootstrap_external>\", line 1458, in find_spec\n",
      "  File \"<frozen importlib._bootstrap_external>\", line 101, in _path_isfile\n",
      "  File \"<frozen importlib._bootstrap_external>\", line 93, in _path_is_mode_type\n",
      "KeyboardInterrupt\n",
      "Traceback (most recent call last):\n",
      "  File \"<frozen importlib._bootstrap_external>\", line 93, in _path_is_mode_type\n",
      "  File \"<frozen importlib._bootstrap_external>\", line 87, in _path_stat\n",
      "FileNotFoundError: [Errno 2] No such file or directory: '/home/smarton/anaconda3/envs/XAI/lib/python3.8/urllib/__init__.cpython-38-x86_64-linux-gnu.so'\n",
      "\n",
      "During handling of the above exception, another exception occurred:\n",
      "\n",
      "Traceback (most recent call last):\n",
      "  File \"/home/smarton/anaconda3/envs/XAI/lib/python3.8/runpy.py\", line 183, in _run_module_as_main\n",
      "    mod_name, mod_spec, code = _get_module_details(mod_name, _Error)\n",
      "  File \"/home/smarton/anaconda3/envs/XAI/lib/python3.8/runpy.py\", line 109, in _get_module_details\n",
      "    __import__(pkg_name)\n",
      "  File \"/home/smarton/anaconda3/envs/XAI/lib/python3.8/site-packages/joblib/__init__.py\", line 113, in <module>\n",
      "    from .memory import Memory, MemorizedResult, register_store_backend\n",
      "  File \"/home/smarton/anaconda3/envs/XAI/lib/python3.8/site-packages/joblib/memory.py\", line 15, in <module>\n",
      "    import pathlib\n",
      "  File \"/home/smarton/anaconda3/envs/XAI/lib/python3.8/pathlib.py\", line 13, in <module>\n",
      "    from urllib.parse import quote_from_bytes as urlquote_from_bytes\n",
      "  File \"<frozen importlib._bootstrap>\", line 991, in _find_and_load\n",
      "  File \"<frozen importlib._bootstrap>\", line 971, in _find_and_load_unlocked\n",
      "  File \"<frozen importlib._bootstrap>\", line 914, in _find_spec\n",
      "  File \"<frozen importlib._bootstrap_external>\", line 1342, in find_spec\n",
      "  File \"<frozen importlib._bootstrap_external>\", line 1314, in _get_spec\n",
      "  File \"<frozen importlib._bootstrap_external>\", line 1458, in find_spec\n",
      "  File \"<frozen importlib._bootstrap_external>\", line 101, in _path_isfile\n",
      "  File \"<frozen importlib._bootstrap_external>\", line 93, in _path_is_mode_type\n",
      "KeyboardInterrupt\n",
      "Traceback (most recent call last):\n",
      "  File \"<frozen importlib._bootstrap_external>\", line 93, in _path_is_mode_type\n",
      "  File \"<frozen importlib._bootstrap_external>\", line 87, in _path_stat\n",
      "FileNotFoundError: [Errno 2] No such file or directory: '/home/smarton/anaconda3/envs/XAI/lib/python3.8/urllib/__init__.cpython-38-x86_64-linux-gnu.so'\n",
      "\n",
      "During handling of the above exception, another exception occurred:\n",
      "\n",
      "Traceback (most recent call last):\n",
      "  File \"/home/smarton/anaconda3/envs/XAI/lib/python3.8/runpy.py\", line 183, in _run_module_as_main\n",
      "    mod_name, mod_spec, code = _get_module_details(mod_name, _Error)\n",
      "  File \"/home/smarton/anaconda3/envs/XAI/lib/python3.8/runpy.py\", line 109, in _get_module_details\n",
      "    __import__(pkg_name)\n",
      "  File \"/home/smarton/anaconda3/envs/XAI/lib/python3.8/site-packages/joblib/__init__.py\", line 113, in <module>\n",
      "    from .memory import Memory, MemorizedResult, register_store_backend\n",
      "  File \"/home/smarton/anaconda3/envs/XAI/lib/python3.8/site-packages/joblib/memory.py\", line 15, in <module>\n",
      "    import pathlib\n",
      "  File \"/home/smarton/anaconda3/envs/XAI/lib/python3.8/pathlib.py\", line 13, in <module>\n",
      "    from urllib.parse import quote_from_bytes as urlquote_from_bytes\n",
      "  File \"<frozen importlib._bootstrap>\", line 991, in _find_and_load\n",
      "  File \"<frozen importlib._bootstrap>\", line 971, in _find_and_load_unlocked\n",
      "  File \"<frozen importlib._bootstrap>\", line 914, in _find_spec\n",
      "  File \"<frozen importlib._bootstrap_external>\", line 1342, in find_spec\n",
      "  File \"<frozen importlib._bootstrap_external>\", line 1314, in _get_spec\n",
      "  File \"<frozen importlib._bootstrap_external>\", line 1458, in find_spec\n",
      "  File \"<frozen importlib._bootstrap_external>\", line 101, in _path_isfile\n",
      "  File \"<frozen importlib._bootstrap_external>\", line 93, in _path_is_mode_type\n",
      "KeyboardInterrupt\n",
      "Traceback (most recent call last):\n",
      "  File \"<frozen importlib._bootstrap_external>\", line 93, in _path_is_mode_type\n",
      "  File \"<frozen importlib._bootstrap_external>\", line 87, in _path_stat\n",
      "FileNotFoundError: [Errno 2] No such file or directory: '/home/smarton/anaconda3/envs/XAI/lib/python3.8/urllib/__init__.cpython-38-x86_64-linux-gnu.so'\n",
      "\n",
      "During handling of the above exception, another exception occurred:\n",
      "\n",
      "Traceback (most recent call last):\n",
      "  File \"/home/smarton/anaconda3/envs/XAI/lib/python3.8/runpy.py\", line 183, in _run_module_as_main\n",
      "    mod_name, mod_spec, code = _get_module_details(mod_name, _Error)\n",
      "  File \"/home/smarton/anaconda3/envs/XAI/lib/python3.8/runpy.py\", line 109, in _get_module_details\n",
      "    __import__(pkg_name)\n",
      "  File \"/home/smarton/anaconda3/envs/XAI/lib/python3.8/site-packages/joblib/__init__.py\", line 113, in <module>\n",
      "    from .memory import Memory, MemorizedResult, register_store_backend\n",
      "  File \"/home/smarton/anaconda3/envs/XAI/lib/python3.8/site-packages/joblib/memory.py\", line 15, in <module>\n",
      "    import pathlib\n",
      "  File \"/home/smarton/anaconda3/envs/XAI/lib/python3.8/pathlib.py\", line 13, in <module>\n",
      "    from urllib.parse import quote_from_bytes as urlquote_from_bytes\n",
      "  File \"<frozen importlib._bootstrap>\", line 991, in _find_and_load\n",
      "  File \"<frozen importlib._bootstrap>\", line 971, in _find_and_load_unlocked\n",
      "  File \"<frozen importlib._bootstrap>\", line 914, in _find_spec\n",
      "  File \"<frozen importlib._bootstrap_external>\", line 1342, in find_spec\n",
      "  File \"<frozen importlib._bootstrap_external>\", line 1314, in _get_spec\n",
      "  File \"<frozen importlib._bootstrap_external>\", line 1458, in find_spec\n",
      "  File \"<frozen importlib._bootstrap_external>\", line 101, in _path_isfile\n",
      "  File \"<frozen importlib._bootstrap_external>\", line 93, in _path_is_mode_type\n",
      "KeyboardInterrupt\n",
      "Traceback (most recent call last):\n",
      "  File \"<frozen importlib._bootstrap_external>\", line 93, in _path_is_mode_type\n",
      "  File \"<frozen importlib._bootstrap_external>\", line 87, in _path_stat\n",
      "FileNotFoundError: [Errno 2] No such file or directory: '/home/smarton/anaconda3/envs/XAI/lib/python3.8/urllib/__init__.cpython-38-x86_64-linux-gnu.so'\n",
      "\n",
      "During handling of the above exception, another exception occurred:\n",
      "\n",
      "Traceback (most recent call last):\n",
      "  File \"/home/smarton/anaconda3/envs/XAI/lib/python3.8/runpy.py\", line 183, in _run_module_as_main\n",
      "    mod_name, mod_spec, code = _get_module_details(mod_name, _Error)\n",
      "  File \"/home/smarton/anaconda3/envs/XAI/lib/python3.8/runpy.py\", line 109, in _get_module_details\n",
      "    __import__(pkg_name)\n",
      "  File \"/home/smarton/anaconda3/envs/XAI/lib/python3.8/site-packages/joblib/__init__.py\", line 113, in <module>\n",
      "    from .memory import Memory, MemorizedResult, register_store_backend\n",
      "  File \"/home/smarton/anaconda3/envs/XAI/lib/python3.8/site-packages/joblib/memory.py\", line 15, in <module>\n",
      "    import pathlib\n",
      "  File \"/home/smarton/anaconda3/envs/XAI/lib/python3.8/pathlib.py\", line 13, in <module>\n",
      "    from urllib.parse import quote_from_bytes as urlquote_from_bytes\n",
      "  File \"<frozen importlib._bootstrap>\", line 991, in _find_and_load\n",
      "  File \"<frozen importlib._bootstrap>\", line 971, in _find_and_load_unlocked\n",
      "  File \"<frozen importlib._bootstrap>\", line 914, in _find_spec\n",
      "  File \"<frozen importlib._bootstrap_external>\", line 1342, in find_spec\n",
      "  File \"<frozen importlib._bootstrap_external>\", line 1314, in _get_spec\n",
      "  File \"<frozen importlib._bootstrap_external>\", line 1458, in find_spec\n",
      "  File \"<frozen importlib._bootstrap_external>\", line 101, in _path_isfile\n",
      "  File \"<frozen importlib._bootstrap_external>\", line 93, in _path_is_mode_type\n",
      "KeyboardInterrupt\n",
      "Traceback (most recent call last):\n",
      "  File \"<frozen importlib._bootstrap_external>\", line 93, in _path_is_mode_type\n",
      "  File \"<frozen importlib._bootstrap_external>\", line 87, in _path_stat\n",
      "FileNotFoundError: [Errno 2] No such file or directory: '/home/smarton/anaconda3/envs/XAI/lib/python3.8/urllib/__init__.cpython-38-x86_64-linux-gnu.so'\n",
      "\n",
      "During handling of the above exception, another exception occurred:\n",
      "\n",
      "Traceback (most recent call last):\n",
      "  File \"/home/smarton/anaconda3/envs/XAI/lib/python3.8/runpy.py\", line 183, in _run_module_as_main\n",
      "    mod_name, mod_spec, code = _get_module_details(mod_name, _Error)\n",
      "  File \"/home/smarton/anaconda3/envs/XAI/lib/python3.8/runpy.py\", line 109, in _get_module_details\n",
      "    __import__(pkg_name)\n",
      "  File \"/home/smarton/anaconda3/envs/XAI/lib/python3.8/site-packages/joblib/__init__.py\", line 113, in <module>\n",
      "    from .memory import Memory, MemorizedResult, register_store_backend\n",
      "  File \"/home/smarton/anaconda3/envs/XAI/lib/python3.8/site-packages/joblib/memory.py\", line 15, in <module>\n",
      "    import pathlib\n",
      "  File \"/home/smarton/anaconda3/envs/XAI/lib/python3.8/pathlib.py\", line 13, in <module>\n",
      "    from urllib.parse import quote_from_bytes as urlquote_from_bytes\n",
      "  File \"<frozen importlib._bootstrap>\", line 991, in _find_and_load\n",
      "  File \"<frozen importlib._bootstrap>\", line 971, in _find_and_load_unlocked\n",
      "  File \"<frozen importlib._bootstrap>\", line 914, in _find_spec\n",
      "  File \"<frozen importlib._bootstrap_external>\", line 1342, in find_spec\n",
      "  File \"<frozen importlib._bootstrap_external>\", line 1314, in _get_spec\n",
      "  File \"<frozen importlib._bootstrap_external>\", line 1458, in find_spec\n",
      "  File \"<frozen importlib._bootstrap_external>\", line 101, in _path_isfile\n",
      "  File \"<frozen importlib._bootstrap_external>\", line 93, in _path_is_mode_type\n",
      "KeyboardInterrupt\n",
      "Traceback (most recent call last):\n",
      "  File \"<frozen importlib._bootstrap_external>\", line 93, in _path_is_mode_type\n",
      "  File \"<frozen importlib._bootstrap_external>\", line 87, in _path_stat\n",
      "FileNotFoundError: [Errno 2] No such file or directory: '/home/smarton/anaconda3/envs/XAI/lib/python3.8/urllib/__init__.cpython-38-x86_64-linux-gnu.so'\n",
      "\n",
      "During handling of the above exception, another exception occurred:\n",
      "\n",
      "Traceback (most recent call last):\n",
      "  File \"/home/smarton/anaconda3/envs/XAI/lib/python3.8/runpy.py\", line 183, in _run_module_as_main\n",
      "    mod_name, mod_spec, code = _get_module_details(mod_name, _Error)\n",
      "  File \"/home/smarton/anaconda3/envs/XAI/lib/python3.8/runpy.py\", line 109, in _get_module_details\n",
      "    __import__(pkg_name)\n",
      "  File \"/home/smarton/anaconda3/envs/XAI/lib/python3.8/site-packages/joblib/__init__.py\", line 113, in <module>\n",
      "    from .memory import Memory, MemorizedResult, register_store_backend\n",
      "  File \"/home/smarton/anaconda3/envs/XAI/lib/python3.8/site-packages/joblib/memory.py\", line 15, in <module>\n",
      "    import pathlib\n",
      "  File \"/home/smarton/anaconda3/envs/XAI/lib/python3.8/pathlib.py\", line 13, in <module>\n",
      "    from urllib.parse import quote_from_bytes as urlquote_from_bytes\n",
      "  File \"<frozen importlib._bootstrap>\", line 991, in _find_and_load\n",
      "  File \"<frozen importlib._bootstrap>\", line 971, in _find_and_load_unlocked\n",
      "  File \"<frozen importlib._bootstrap>\", line 914, in _find_spec\n",
      "  File \"<frozen importlib._bootstrap_external>\", line 1342, in find_spec\n",
      "  File \"<frozen importlib._bootstrap_external>\", line 1314, in _get_spec\n",
      "  File \"<frozen importlib._bootstrap_external>\", line 1458, in find_spec\n",
      "  File \"<frozen importlib._bootstrap_external>\", line 101, in _path_isfile\n",
      "  File \"<frozen importlib._bootstrap_external>\", line 93, in _path_is_mode_type\n",
      "KeyboardInterrupt\n",
      "Traceback (most recent call last):\n",
      "  File \"<frozen importlib._bootstrap_external>\", line 93, in _path_is_mode_type\n",
      "  File \"<frozen importlib._bootstrap_external>\", line 87, in _path_stat\n",
      "FileNotFoundError: [Errno 2] No such file or directory: '/home/smarton/anaconda3/envs/XAI/lib/python3.8/urllib/__init__.cpython-38-x86_64-linux-gnu.so'\n",
      "\n",
      "During handling of the above exception, another exception occurred:\n",
      "\n",
      "Traceback (most recent call last):\n",
      "  File \"/home/smarton/anaconda3/envs/XAI/lib/python3.8/runpy.py\", line 183, in _run_module_as_main\n",
      "    mod_name, mod_spec, code = _get_module_details(mod_name, _Error)\n",
      "  File \"/home/smarton/anaconda3/envs/XAI/lib/python3.8/runpy.py\", line 109, in _get_module_details\n",
      "    __import__(pkg_name)\n",
      "  File \"/home/smarton/anaconda3/envs/XAI/lib/python3.8/site-packages/joblib/__init__.py\", line 113, in <module>\n",
      "    from .memory import Memory, MemorizedResult, register_store_backend\n",
      "  File \"/home/smarton/anaconda3/envs/XAI/lib/python3.8/site-packages/joblib/memory.py\", line 15, in <module>\n",
      "    import pathlib\n",
      "  File \"/home/smarton/anaconda3/envs/XAI/lib/python3.8/pathlib.py\", line 13, in <module>\n",
      "    from urllib.parse import quote_from_bytes as urlquote_from_bytes\n",
      "  File \"<frozen importlib._bootstrap>\", line 991, in _find_and_load\n",
      "  File \"<frozen importlib._bootstrap>\", line 971, in _find_and_load_unlocked\n",
      "  File \"<frozen importlib._bootstrap>\", line 914, in _find_spec\n",
      "  File \"<frozen importlib._bootstrap_external>\", line 1342, in find_spec\n",
      "  File \"<frozen importlib._bootstrap_external>\", line 1314, in _get_spec\n",
      "  File \"<frozen importlib._bootstrap_external>\", line 1458, in find_spec\n",
      "  File \"<frozen importlib._bootstrap_external>\", line 101, in _path_isfile\n",
      "  File \"<frozen importlib._bootstrap_external>\", line 93, in _path_is_mode_type\n",
      "KeyboardInterrupt\n",
      "Traceback (most recent call last):\n",
      "  File \"<frozen importlib._bootstrap_external>\", line 93, in _path_is_mode_type\n",
      "  File \"<frozen importlib._bootstrap_external>\", line 87, in _path_stat\n",
      "FileNotFoundError: [Errno 2] No such file or directory: '/home/smarton/anaconda3/envs/XAI/lib/python3.8/urllib/__init__.cpython-38-x86_64-linux-gnu.so'\n",
      "\n",
      "During handling of the above exception, another exception occurred:\n",
      "\n",
      "Traceback (most recent call last):\n",
      "  File \"/home/smarton/anaconda3/envs/XAI/lib/python3.8/runpy.py\", line 183, in _run_module_as_main\n",
      "    mod_name, mod_spec, code = _get_module_details(mod_name, _Error)\n",
      "  File \"/home/smarton/anaconda3/envs/XAI/lib/python3.8/runpy.py\", line 109, in _get_module_details\n",
      "    __import__(pkg_name)\n",
      "  File \"/home/smarton/anaconda3/envs/XAI/lib/python3.8/site-packages/joblib/__init__.py\", line 113, in <module>\n",
      "    from .memory import Memory, MemorizedResult, register_store_backend\n",
      "  File \"/home/smarton/anaconda3/envs/XAI/lib/python3.8/site-packages/joblib/memory.py\", line 15, in <module>\n",
      "    import pathlib\n",
      "  File \"/home/smarton/anaconda3/envs/XAI/lib/python3.8/pathlib.py\", line 13, in <module>\n",
      "    from urllib.parse import quote_from_bytes as urlquote_from_bytes\n",
      "  File \"<frozen importlib._bootstrap>\", line 991, in _find_and_load\n",
      "  File \"<frozen importlib._bootstrap>\", line 971, in _find_and_load_unlocked\n",
      "  File \"<frozen importlib._bootstrap>\", line 914, in _find_spec\n",
      "  File \"<frozen importlib._bootstrap_external>\", line 1342, in find_spec\n",
      "  File \"<frozen importlib._bootstrap_external>\", line 1314, in _get_spec\n",
      "  File \"<frozen importlib._bootstrap_external>\", line 1458, in find_spec\n",
      "  File \"<frozen importlib._bootstrap_external>\", line 101, in _path_isfile\n",
      "  File \"<frozen importlib._bootstrap_external>\", line 93, in _path_is_mode_type\n",
      "KeyboardInterrupt\n",
      "Traceback (most recent call last):\n",
      "  File \"<frozen importlib._bootstrap_external>\", line 93, in _path_is_mode_type\n",
      "  File \"<frozen importlib._bootstrap_external>\", line 87, in _path_stat\n",
      "FileNotFoundError: [Errno 2] No such file or directory: '/home/smarton/anaconda3/envs/XAI/lib/python3.8/urllib/__init__.cpython-38-x86_64-linux-gnu.so'\n",
      "\n",
      "During handling of the above exception, another exception occurred:\n",
      "\n",
      "Traceback (most recent call last):\n",
      "  File \"/home/smarton/anaconda3/envs/XAI/lib/python3.8/runpy.py\", line 183, in _run_module_as_main\n",
      "    mod_name, mod_spec, code = _get_module_details(mod_name, _Error)\n",
      "  File \"/home/smarton/anaconda3/envs/XAI/lib/python3.8/runpy.py\", line 109, in _get_module_details\n",
      "    __import__(pkg_name)\n",
      "  File \"/home/smarton/anaconda3/envs/XAI/lib/python3.8/site-packages/joblib/__init__.py\", line 113, in <module>\n",
      "    from .memory import Memory, MemorizedResult, register_store_backend\n",
      "  File \"/home/smarton/anaconda3/envs/XAI/lib/python3.8/site-packages/joblib/memory.py\", line 15, in <module>\n",
      "    import pathlib\n",
      "  File \"/home/smarton/anaconda3/envs/XAI/lib/python3.8/pathlib.py\", line 13, in <module>\n",
      "    from urllib.parse import quote_from_bytes as urlquote_from_bytes\n",
      "  File \"<frozen importlib._bootstrap>\", line 991, in _find_and_load\n",
      "  File \"<frozen importlib._bootstrap>\", line 971, in _find_and_load_unlocked\n",
      "  File \"<frozen importlib._bootstrap>\", line 914, in _find_spec\n",
      "  File \"<frozen importlib._bootstrap_external>\", line 1342, in find_spec\n",
      "  File \"<frozen importlib._bootstrap_external>\", line 1314, in _get_spec\n",
      "  File \"<frozen importlib._bootstrap_external>\", line 1458, in find_spec\n",
      "  File \"<frozen importlib._bootstrap_external>\", line 101, in _path_isfile\n",
      "  File \"<frozen importlib._bootstrap_external>\", line 93, in _path_is_mode_type\n",
      "KeyboardInterrupt\n",
      "Traceback (most recent call last):\n",
      "  File \"<frozen importlib._bootstrap_external>\", line 93, in _path_is_mode_type\n",
      "  File \"<frozen importlib._bootstrap_external>\", line 87, in _path_stat\n",
      "FileNotFoundError: [Errno 2] No such file or directory: '/home/smarton/anaconda3/envs/XAI/lib/python3.8/urllib/__init__.cpython-38-x86_64-linux-gnu.so'\n",
      "\n",
      "During handling of the above exception, another exception occurred:\n",
      "\n",
      "Traceback (most recent call last):\n",
      "  File \"/home/smarton/anaconda3/envs/XAI/lib/python3.8/runpy.py\", line 183, in _run_module_as_main\n",
      "    mod_name, mod_spec, code = _get_module_details(mod_name, _Error)\n",
      "  File \"/home/smarton/anaconda3/envs/XAI/lib/python3.8/runpy.py\", line 109, in _get_module_details\n",
      "    __import__(pkg_name)\n",
      "  File \"/home/smarton/anaconda3/envs/XAI/lib/python3.8/site-packages/joblib/__init__.py\", line 113, in <module>\n",
      "    from .memory import Memory, MemorizedResult, register_store_backend\n",
      "  File \"/home/smarton/anaconda3/envs/XAI/lib/python3.8/site-packages/joblib/memory.py\", line 15, in <module>\n",
      "    import pathlib\n",
      "  File \"/home/smarton/anaconda3/envs/XAI/lib/python3.8/pathlib.py\", line 13, in <module>\n",
      "    from urllib.parse import quote_from_bytes as urlquote_from_bytes\n",
      "  File \"<frozen importlib._bootstrap>\", line 991, in _find_and_load\n",
      "  File \"<frozen importlib._bootstrap>\", line 971, in _find_and_load_unlocked\n",
      "  File \"<frozen importlib._bootstrap>\", line 914, in _find_spec\n",
      "  File \"<frozen importlib._bootstrap_external>\", line 1342, in find_spec\n",
      "  File \"<frozen importlib._bootstrap_external>\", line 1314, in _get_spec\n",
      "  File \"<frozen importlib._bootstrap_external>\", line 1458, in find_spec\n",
      "  File \"<frozen importlib._bootstrap_external>\", line 101, in _path_isfile\n",
      "  File \"<frozen importlib._bootstrap_external>\", line 93, in _path_is_mode_type\n",
      "KeyboardInterrupt\n",
      "Traceback (most recent call last):\n",
      "  File \"<frozen importlib._bootstrap_external>\", line 93, in _path_is_mode_type\n",
      "  File \"<frozen importlib._bootstrap_external>\", line 87, in _path_stat\n",
      "FileNotFoundError: [Errno 2] No such file or directory: '/home/smarton/anaconda3/envs/XAI/lib/python3.8/urllib/__init__.cpython-38-x86_64-linux-gnu.so'\n",
      "\n",
      "During handling of the above exception, another exception occurred:\n",
      "\n",
      "Traceback (most recent call last):\n",
      "  File \"/home/smarton/anaconda3/envs/XAI/lib/python3.8/runpy.py\", line 183, in _run_module_as_main\n",
      "    mod_name, mod_spec, code = _get_module_details(mod_name, _Error)\n",
      "  File \"/home/smarton/anaconda3/envs/XAI/lib/python3.8/runpy.py\", line 109, in _get_module_details\n",
      "    __import__(pkg_name)\n",
      "  File \"/home/smarton/anaconda3/envs/XAI/lib/python3.8/site-packages/joblib/__init__.py\", line 113, in <module>\n",
      "    from .memory import Memory, MemorizedResult, register_store_backend\n",
      "  File \"/home/smarton/anaconda3/envs/XAI/lib/python3.8/site-packages/joblib/memory.py\", line 15, in <module>\n",
      "    import pathlib\n",
      "  File \"/home/smarton/anaconda3/envs/XAI/lib/python3.8/pathlib.py\", line 13, in <module>\n",
      "    from urllib.parse import quote_from_bytes as urlquote_from_bytes\n",
      "  File \"<frozen importlib._bootstrap>\", line 991, in _find_and_load\n",
      "  File \"<frozen importlib._bootstrap>\", line 971, in _find_and_load_unlocked\n",
      "  File \"<frozen importlib._bootstrap>\", line 914, in _find_spec\n",
      "  File \"<frozen importlib._bootstrap_external>\", line 1342, in find_spec\n",
      "  File \"<frozen importlib._bootstrap_external>\", line 1314, in _get_spec\n",
      "  File \"<frozen importlib._bootstrap_external>\", line 1458, in find_spec\n",
      "  File \"<frozen importlib._bootstrap_external>\", line 101, in _path_isfile\n",
      "  File \"<frozen importlib._bootstrap_external>\", line 93, in _path_is_mode_type\n",
      "KeyboardInterrupt\n",
      "Traceback (most recent call last):\n",
      "  File \"<frozen importlib._bootstrap_external>\", line 93, in _path_is_mode_type\n",
      "  File \"<frozen importlib._bootstrap_external>\", line 87, in _path_stat\n",
      "FileNotFoundError: [Errno 2] No such file or directory: '/home/smarton/anaconda3/envs/XAI/lib/python3.8/urllib/__init__.cpython-38-x86_64-linux-gnu.so'\n",
      "\n",
      "During handling of the above exception, another exception occurred:\n",
      "\n",
      "Traceback (most recent call last):\n",
      "  File \"/home/smarton/anaconda3/envs/XAI/lib/python3.8/runpy.py\", line 183, in _run_module_as_main\n",
      "    mod_name, mod_spec, code = _get_module_details(mod_name, _Error)\n",
      "  File \"/home/smarton/anaconda3/envs/XAI/lib/python3.8/runpy.py\", line 109, in _get_module_details\n",
      "    __import__(pkg_name)\n",
      "  File \"/home/smarton/anaconda3/envs/XAI/lib/python3.8/site-packages/joblib/__init__.py\", line 113, in <module>\n",
      "    from .memory import Memory, MemorizedResult, register_store_backend\n",
      "  File \"/home/smarton/anaconda3/envs/XAI/lib/python3.8/site-packages/joblib/memory.py\", line 15, in <module>\n",
      "    import pathlib\n",
      "  File \"/home/smarton/anaconda3/envs/XAI/lib/python3.8/pathlib.py\", line 13, in <module>\n",
      "    from urllib.parse import quote_from_bytes as urlquote_from_bytes\n",
      "  File \"<frozen importlib._bootstrap>\", line 991, in _find_and_load\n",
      "  File \"<frozen importlib._bootstrap>\", line 971, in _find_and_load_unlocked\n",
      "  File \"<frozen importlib._bootstrap>\", line 914, in _find_spec\n",
      "  File \"<frozen importlib._bootstrap_external>\", line 1342, in find_spec\n",
      "  File \"<frozen importlib._bootstrap_external>\", line 1314, in _get_spec\n",
      "  File \"<frozen importlib._bootstrap_external>\", line 1458, in find_spec\n",
      "  File \"<frozen importlib._bootstrap_external>\", line 101, in _path_isfile\n",
      "  File \"<frozen importlib._bootstrap_external>\", line 93, in _path_is_mode_type\n",
      "KeyboardInterrupt\n",
      "Traceback (most recent call last):\n",
      "  File \"<frozen importlib._bootstrap_external>\", line 93, in _path_is_mode_type\n",
      "  File \"<frozen importlib._bootstrap_external>\", line 87, in _path_stat\n",
      "FileNotFoundError: [Errno 2] No such file or directory: '/home/smarton/anaconda3/envs/XAI/lib/python3.8/urllib/__init__.cpython-38-x86_64-linux-gnu.so'\n",
      "\n",
      "During handling of the above exception, another exception occurred:\n",
      "\n",
      "Traceback (most recent call last):\n",
      "  File \"/home/smarton/anaconda3/envs/XAI/lib/python3.8/runpy.py\", line 183, in _run_module_as_main\n",
      "    mod_name, mod_spec, code = _get_module_details(mod_name, _Error)\n",
      "  File \"/home/smarton/anaconda3/envs/XAI/lib/python3.8/runpy.py\", line 109, in _get_module_details\n",
      "    __import__(pkg_name)\n",
      "  File \"/home/smarton/anaconda3/envs/XAI/lib/python3.8/site-packages/joblib/__init__.py\", line 113, in <module>\n",
      "    from .memory import Memory, MemorizedResult, register_store_backend\n",
      "  File \"/home/smarton/anaconda3/envs/XAI/lib/python3.8/site-packages/joblib/memory.py\", line 15, in <module>\n",
      "    import pathlib\n",
      "  File \"/home/smarton/anaconda3/envs/XAI/lib/python3.8/pathlib.py\", line 13, in <module>\n",
      "    from urllib.parse import quote_from_bytes as urlquote_from_bytes\n",
      "  File \"<frozen importlib._bootstrap>\", line 991, in _find_and_load\n",
      "  File \"<frozen importlib._bootstrap>\", line 971, in _find_and_load_unlocked\n",
      "  File \"<frozen importlib._bootstrap>\", line 914, in _find_spec\n",
      "  File \"<frozen importlib._bootstrap_external>\", line 1342, in find_spec\n",
      "  File \"<frozen importlib._bootstrap_external>\", line 1314, in _get_spec\n",
      "  File \"<frozen importlib._bootstrap_external>\", line 1458, in find_spec\n",
      "  File \"<frozen importlib._bootstrap_external>\", line 101, in _path_isfile\n",
      "  File \"<frozen importlib._bootstrap_external>\", line 93, in _path_is_mode_type\n",
      "KeyboardInterrupt\n",
      "Traceback (most recent call last):\n",
      "  File \"<frozen importlib._bootstrap_external>\", line 93, in _path_is_mode_type\n",
      "  File \"<frozen importlib._bootstrap_external>\", line 87, in _path_stat\n",
      "FileNotFoundError: [Errno 2] No such file or directory: '/home/smarton/anaconda3/envs/XAI/lib/python3.8/urllib/__init__.cpython-38-x86_64-linux-gnu.so'\n",
      "\n",
      "During handling of the above exception, another exception occurred:\n",
      "\n",
      "Traceback (most recent call last):\n",
      "  File \"/home/smarton/anaconda3/envs/XAI/lib/python3.8/runpy.py\", line 183, in _run_module_as_main\n",
      "    mod_name, mod_spec, code = _get_module_details(mod_name, _Error)\n",
      "  File \"/home/smarton/anaconda3/envs/XAI/lib/python3.8/runpy.py\", line 109, in _get_module_details\n",
      "    __import__(pkg_name)\n",
      "  File \"/home/smarton/anaconda3/envs/XAI/lib/python3.8/site-packages/joblib/__init__.py\", line 113, in <module>\n",
      "    from .memory import Memory, MemorizedResult, register_store_backend\n",
      "  File \"/home/smarton/anaconda3/envs/XAI/lib/python3.8/site-packages/joblib/memory.py\", line 15, in <module>\n",
      "    import pathlib\n",
      "  File \"/home/smarton/anaconda3/envs/XAI/lib/python3.8/pathlib.py\", line 13, in <module>\n",
      "    from urllib.parse import quote_from_bytes as urlquote_from_bytes\n",
      "  File \"<frozen importlib._bootstrap>\", line 991, in _find_and_load\n",
      "  File \"<frozen importlib._bootstrap>\", line 971, in _find_and_load_unlocked\n",
      "  File \"<frozen importlib._bootstrap>\", line 914, in _find_spec\n",
      "  File \"<frozen importlib._bootstrap_external>\", line 1342, in find_spec\n",
      "  File \"<frozen importlib._bootstrap_external>\", line 1314, in _get_spec\n",
      "  File \"<frozen importlib._bootstrap_external>\", line 1458, in find_spec\n",
      "  File \"<frozen importlib._bootstrap_external>\", line 101, in _path_isfile\n",
      "  File \"<frozen importlib._bootstrap_external>\", line 93, in _path_is_mode_type\n",
      "KeyboardInterrupt\n",
      "Traceback (most recent call last):\n",
      "  File \"<frozen importlib._bootstrap_external>\", line 93, in _path_is_mode_type\n",
      "  File \"<frozen importlib._bootstrap_external>\", line 87, in _path_stat\n",
      "FileNotFoundError: [Errno 2] No such file or directory: '/home/smarton/anaconda3/envs/XAI/lib/python3.8/urllib/__init__.cpython-38-x86_64-linux-gnu.so'\n",
      "\n",
      "During handling of the above exception, another exception occurred:\n",
      "\n",
      "Traceback (most recent call last):\n",
      "  File \"/home/smarton/anaconda3/envs/XAI/lib/python3.8/runpy.py\", line 183, in _run_module_as_main\n",
      "    mod_name, mod_spec, code = _get_module_details(mod_name, _Error)\n",
      "  File \"/home/smarton/anaconda3/envs/XAI/lib/python3.8/runpy.py\", line 109, in _get_module_details\n",
      "    __import__(pkg_name)\n",
      "  File \"/home/smarton/anaconda3/envs/XAI/lib/python3.8/site-packages/joblib/__init__.py\", line 113, in <module>\n",
      "    from .memory import Memory, MemorizedResult, register_store_backend\n",
      "  File \"/home/smarton/anaconda3/envs/XAI/lib/python3.8/site-packages/joblib/memory.py\", line 15, in <module>\n",
      "    import pathlib\n",
      "  File \"/home/smarton/anaconda3/envs/XAI/lib/python3.8/pathlib.py\", line 13, in <module>\n",
      "    from urllib.parse import quote_from_bytes as urlquote_from_bytes\n",
      "  File \"<frozen importlib._bootstrap>\", line 991, in _find_and_load\n",
      "  File \"<frozen importlib._bootstrap>\", line 971, in _find_and_load_unlocked\n",
      "  File \"<frozen importlib._bootstrap>\", line 914, in _find_spec\n",
      "  File \"<frozen importlib._bootstrap_external>\", line 1342, in find_spec\n",
      "  File \"<frozen importlib._bootstrap_external>\", line 1314, in _get_spec\n",
      "  File \"<frozen importlib._bootstrap_external>\", line 1458, in find_spec\n",
      "  File \"<frozen importlib._bootstrap_external>\", line 101, in _path_isfile\n",
      "  File \"<frozen importlib._bootstrap_external>\", line 93, in _path_is_mode_type\n",
      "KeyboardInterrupt\n",
      "Traceback (most recent call last):\n",
      "  File \"<frozen importlib._bootstrap_external>\", line 93, in _path_is_mode_type\n",
      "  File \"<frozen importlib._bootstrap_external>\", line 87, in _path_stat\n",
      "FileNotFoundError: [Errno 2] No such file or directory: '/home/smarton/anaconda3/envs/XAI/lib/python3.8/urllib/__init__.cpython-38-x86_64-linux-gnu.so'\n",
      "\n",
      "During handling of the above exception, another exception occurred:\n",
      "\n",
      "Traceback (most recent call last):\n",
      "  File \"/home/smarton/anaconda3/envs/XAI/lib/python3.8/runpy.py\", line 183, in _run_module_as_main\n",
      "    mod_name, mod_spec, code = _get_module_details(mod_name, _Error)\n",
      "  File \"/home/smarton/anaconda3/envs/XAI/lib/python3.8/runpy.py\", line 109, in _get_module_details\n",
      "    __import__(pkg_name)\n",
      "  File \"/home/smarton/anaconda3/envs/XAI/lib/python3.8/site-packages/joblib/__init__.py\", line 113, in <module>\n",
      "    from .memory import Memory, MemorizedResult, register_store_backend\n",
      "  File \"/home/smarton/anaconda3/envs/XAI/lib/python3.8/site-packages/joblib/memory.py\", line 15, in <module>\n",
      "    import pathlib\n",
      "  File \"/home/smarton/anaconda3/envs/XAI/lib/python3.8/pathlib.py\", line 13, in <module>\n",
      "    from urllib.parse import quote_from_bytes as urlquote_from_bytes\n",
      "  File \"<frozen importlib._bootstrap>\", line 991, in _find_and_load\n",
      "  File \"<frozen importlib._bootstrap>\", line 971, in _find_and_load_unlocked\n",
      "  File \"<frozen importlib._bootstrap>\", line 914, in _find_spec\n",
      "  File \"<frozen importlib._bootstrap_external>\", line 1342, in find_spec\n",
      "  File \"<frozen importlib._bootstrap_external>\", line 1314, in _get_spec\n",
      "  File \"<frozen importlib._bootstrap_external>\", line 1458, in find_spec\n",
      "  File \"<frozen importlib._bootstrap_external>\", line 101, in _path_isfile\n",
      "  File \"<frozen importlib._bootstrap_external>\", line 93, in _path_is_mode_type\n",
      "KeyboardInterrupt\n",
      "Traceback (most recent call last):\n",
      "  File \"<frozen importlib._bootstrap_external>\", line 93, in _path_is_mode_type\n",
      "  File \"<frozen importlib._bootstrap_external>\", line 87, in _path_stat\n",
      "FileNotFoundError: [Errno 2] No such file or directory: '/home/smarton/anaconda3/envs/XAI/lib/python3.8/urllib/__init__.cpython-38-x86_64-linux-gnu.so'\n",
      "\n",
      "During handling of the above exception, another exception occurred:\n",
      "\n",
      "Traceback (most recent call last):\n",
      "  File \"/home/smarton/anaconda3/envs/XAI/lib/python3.8/runpy.py\", line 183, in _run_module_as_main\n",
      "    mod_name, mod_spec, code = _get_module_details(mod_name, _Error)\n",
      "  File \"/home/smarton/anaconda3/envs/XAI/lib/python3.8/runpy.py\", line 109, in _get_module_details\n",
      "    __import__(pkg_name)\n",
      "  File \"/home/smarton/anaconda3/envs/XAI/lib/python3.8/site-packages/joblib/__init__.py\", line 113, in <module>\n",
      "    from .memory import Memory, MemorizedResult, register_store_backend\n",
      "  File \"/home/smarton/anaconda3/envs/XAI/lib/python3.8/site-packages/joblib/memory.py\", line 15, in <module>\n",
      "    import pathlib\n",
      "  File \"/home/smarton/anaconda3/envs/XAI/lib/python3.8/pathlib.py\", line 13, in <module>\n",
      "    from urllib.parse import quote_from_bytes as urlquote_from_bytes\n",
      "  File \"<frozen importlib._bootstrap>\", line 991, in _find_and_load\n",
      "  File \"<frozen importlib._bootstrap>\", line 971, in _find_and_load_unlocked\n",
      "  File \"<frozen importlib._bootstrap>\", line 914, in _find_spec\n",
      "  File \"<frozen importlib._bootstrap_external>\", line 1342, in find_spec\n",
      "  File \"<frozen importlib._bootstrap_external>\", line 1314, in _get_spec\n",
      "  File \"<frozen importlib._bootstrap_external>\", line 1458, in find_spec\n",
      "  File \"<frozen importlib._bootstrap_external>\", line 101, in _path_isfile\n",
      "  File \"<frozen importlib._bootstrap_external>\", line 93, in _path_is_mode_type\n",
      "KeyboardInterrupt\n",
      "Traceback (most recent call last):\n",
      "  File \"<frozen importlib._bootstrap_external>\", line 93, in _path_is_mode_type\n",
      "  File \"<frozen importlib._bootstrap_external>\", line 87, in _path_stat\n",
      "FileNotFoundError: [Errno 2] No such file or directory: '/home/smarton/anaconda3/envs/XAI/lib/python3.8/urllib/__init__.cpython-38-x86_64-linux-gnu.so'\n",
      "\n",
      "During handling of the above exception, another exception occurred:\n",
      "\n",
      "Traceback (most recent call last):\n",
      "  File \"/home/smarton/anaconda3/envs/XAI/lib/python3.8/runpy.py\", line 183, in _run_module_as_main\n",
      "    mod_name, mod_spec, code = _get_module_details(mod_name, _Error)\n",
      "  File \"/home/smarton/anaconda3/envs/XAI/lib/python3.8/runpy.py\", line 109, in _get_module_details\n",
      "    __import__(pkg_name)\n",
      "  File \"/home/smarton/anaconda3/envs/XAI/lib/python3.8/site-packages/joblib/__init__.py\", line 113, in <module>\n",
      "    from .memory import Memory, MemorizedResult, register_store_backend\n",
      "  File \"/home/smarton/anaconda3/envs/XAI/lib/python3.8/site-packages/joblib/memory.py\", line 15, in <module>\n",
      "    import pathlib\n",
      "  File \"/home/smarton/anaconda3/envs/XAI/lib/python3.8/pathlib.py\", line 13, in <module>\n",
      "    from urllib.parse import quote_from_bytes as urlquote_from_bytes\n",
      "  File \"<frozen importlib._bootstrap>\", line 991, in _find_and_load\n",
      "  File \"<frozen importlib._bootstrap>\", line 971, in _find_and_load_unlocked\n",
      "  File \"<frozen importlib._bootstrap>\", line 914, in _find_spec\n",
      "  File \"<frozen importlib._bootstrap_external>\", line 1342, in find_spec\n",
      "  File \"<frozen importlib._bootstrap_external>\", line 1314, in _get_spec\n",
      "  File \"<frozen importlib._bootstrap_external>\", line 1458, in find_spec\n",
      "  File \"<frozen importlib._bootstrap_external>\", line 101, in _path_isfile\n",
      "  File \"<frozen importlib._bootstrap_external>\", line 93, in _path_is_mode_type\n",
      "KeyboardInterrupt\n",
      "Traceback (most recent call last):\n",
      "  File \"<frozen importlib._bootstrap_external>\", line 93, in _path_is_mode_type\n",
      "  File \"<frozen importlib._bootstrap_external>\", line 87, in _path_stat\n",
      "FileNotFoundError: [Errno 2] No such file or directory: '/home/smarton/anaconda3/envs/XAI/lib/python3.8/urllib/__init__.cpython-38-x86_64-linux-gnu.so'\n",
      "\n",
      "During handling of the above exception, another exception occurred:\n",
      "\n",
      "Traceback (most recent call last):\n",
      "  File \"/home/smarton/anaconda3/envs/XAI/lib/python3.8/runpy.py\", line 183, in _run_module_as_main\n",
      "    mod_name, mod_spec, code = _get_module_details(mod_name, _Error)\n",
      "  File \"/home/smarton/anaconda3/envs/XAI/lib/python3.8/runpy.py\", line 109, in _get_module_details\n",
      "    __import__(pkg_name)\n",
      "  File \"/home/smarton/anaconda3/envs/XAI/lib/python3.8/site-packages/joblib/__init__.py\", line 113, in <module>\n",
      "    from .memory import Memory, MemorizedResult, register_store_backend\n",
      "  File \"/home/smarton/anaconda3/envs/XAI/lib/python3.8/site-packages/joblib/memory.py\", line 15, in <module>\n",
      "    import pathlib\n",
      "  File \"/home/smarton/anaconda3/envs/XAI/lib/python3.8/pathlib.py\", line 13, in <module>\n",
      "    from urllib.parse import quote_from_bytes as urlquote_from_bytes\n",
      "  File \"<frozen importlib._bootstrap>\", line 991, in _find_and_load\n",
      "  File \"<frozen importlib._bootstrap>\", line 971, in _find_and_load_unlocked\n",
      "  File \"<frozen importlib._bootstrap>\", line 914, in _find_spec\n",
      "  File \"<frozen importlib._bootstrap_external>\", line 1342, in find_spec\n",
      "  File \"<frozen importlib._bootstrap_external>\", line 1314, in _get_spec\n",
      "  File \"<frozen importlib._bootstrap_external>\", line 1458, in find_spec\n",
      "  File \"<frozen importlib._bootstrap_external>\", line 101, in _path_isfile\n",
      "  File \"<frozen importlib._bootstrap_external>\", line 93, in _path_is_mode_type\n",
      "KeyboardInterrupt\n",
      "Traceback (most recent call last):\n",
      "  File \"<frozen importlib._bootstrap_external>\", line 93, in _path_is_mode_type\n",
      "  File \"<frozen importlib._bootstrap_external>\", line 87, in _path_stat\n",
      "FileNotFoundError: [Errno 2] No such file or directory: '/home/smarton/anaconda3/envs/XAI/lib/python3.8/urllib/__init__.cpython-38-x86_64-linux-gnu.so'\n",
      "\n",
      "During handling of the above exception, another exception occurred:\n",
      "\n",
      "Traceback (most recent call last):\n",
      "  File \"/home/smarton/anaconda3/envs/XAI/lib/python3.8/runpy.py\", line 183, in _run_module_as_main\n",
      "    mod_name, mod_spec, code = _get_module_details(mod_name, _Error)\n",
      "  File \"/home/smarton/anaconda3/envs/XAI/lib/python3.8/runpy.py\", line 109, in _get_module_details\n",
      "    __import__(pkg_name)\n",
      "  File \"/home/smarton/anaconda3/envs/XAI/lib/python3.8/site-packages/joblib/__init__.py\", line 113, in <module>\n",
      "    from .memory import Memory, MemorizedResult, register_store_backend\n",
      "  File \"/home/smarton/anaconda3/envs/XAI/lib/python3.8/site-packages/joblib/memory.py\", line 15, in <module>\n",
      "    import pathlib\n",
      "  File \"/home/smarton/anaconda3/envs/XAI/lib/python3.8/pathlib.py\", line 13, in <module>\n",
      "    from urllib.parse import quote_from_bytes as urlquote_from_bytes\n",
      "  File \"<frozen importlib._bootstrap>\", line 991, in _find_and_load\n",
      "  File \"<frozen importlib._bootstrap>\", line 971, in _find_and_load_unlocked\n",
      "  File \"<frozen importlib._bootstrap>\", line 914, in _find_spec\n",
      "  File \"<frozen importlib._bootstrap_external>\", line 1342, in find_spec\n",
      "  File \"<frozen importlib._bootstrap_external>\", line 1314, in _get_spec\n",
      "  File \"<frozen importlib._bootstrap_external>\", line 1458, in find_spec\n",
      "  File \"<frozen importlib._bootstrap_external>\", line 101, in _path_isfile\n",
      "  File \"<frozen importlib._bootstrap_external>\", line 93, in _path_is_mode_type\n",
      "KeyboardInterrupt\n",
      "Traceback (most recent call last):\n",
      "  File \"<frozen importlib._bootstrap_external>\", line 93, in _path_is_mode_type\n",
      "  File \"<frozen importlib._bootstrap_external>\", line 87, in _path_stat\n",
      "FileNotFoundError: [Errno 2] No such file or directory: '/home/smarton/anaconda3/envs/XAI/lib/python3.8/urllib/__init__.cpython-38-x86_64-linux-gnu.so'\n",
      "\n",
      "During handling of the above exception, another exception occurred:\n",
      "\n",
      "Traceback (most recent call last):\n",
      "  File \"/home/smarton/anaconda3/envs/XAI/lib/python3.8/runpy.py\", line 183, in _run_module_as_main\n",
      "    mod_name, mod_spec, code = _get_module_details(mod_name, _Error)\n",
      "  File \"/home/smarton/anaconda3/envs/XAI/lib/python3.8/runpy.py\", line 109, in _get_module_details\n",
      "    __import__(pkg_name)\n",
      "  File \"/home/smarton/anaconda3/envs/XAI/lib/python3.8/site-packages/joblib/__init__.py\", line 113, in <module>\n",
      "    from .memory import Memory, MemorizedResult, register_store_backend\n",
      "  File \"/home/smarton/anaconda3/envs/XAI/lib/python3.8/site-packages/joblib/memory.py\", line 15, in <module>\n",
      "    import pathlib\n",
      "  File \"/home/smarton/anaconda3/envs/XAI/lib/python3.8/pathlib.py\", line 13, in <module>\n",
      "    from urllib.parse import quote_from_bytes as urlquote_from_bytes\n",
      "  File \"<frozen importlib._bootstrap>\", line 991, in _find_and_load\n",
      "  File \"<frozen importlib._bootstrap>\", line 971, in _find_and_load_unlocked\n",
      "  File \"<frozen importlib._bootstrap>\", line 914, in _find_spec\n",
      "  File \"<frozen importlib._bootstrap_external>\", line 1342, in find_spec\n",
      "  File \"<frozen importlib._bootstrap_external>\", line 1314, in _get_spec\n",
      "  File \"<frozen importlib._bootstrap_external>\", line 1458, in find_spec\n",
      "  File \"<frozen importlib._bootstrap_external>\", line 101, in _path_isfile\n",
      "  File \"<frozen importlib._bootstrap_external>\", line 93, in _path_is_mode_type\n",
      "KeyboardInterrupt\n",
      "Traceback (most recent call last):\n",
      "  File \"<frozen importlib._bootstrap_external>\", line 93, in _path_is_mode_type\n",
      "  File \"<frozen importlib._bootstrap_external>\", line 87, in _path_stat\n",
      "FileNotFoundError: [Errno 2] No such file or directory: '/home/smarton/anaconda3/envs/XAI/lib/python3.8/urllib/__init__.cpython-38-x86_64-linux-gnu.so'\n",
      "\n",
      "During handling of the above exception, another exception occurred:\n",
      "\n",
      "Traceback (most recent call last):\n",
      "  File \"/home/smarton/anaconda3/envs/XAI/lib/python3.8/runpy.py\", line 183, in _run_module_as_main\n",
      "    mod_name, mod_spec, code = _get_module_details(mod_name, _Error)\n",
      "  File \"/home/smarton/anaconda3/envs/XAI/lib/python3.8/runpy.py\", line 109, in _get_module_details\n",
      "    __import__(pkg_name)\n",
      "  File \"/home/smarton/anaconda3/envs/XAI/lib/python3.8/site-packages/joblib/__init__.py\", line 113, in <module>\n",
      "    from .memory import Memory, MemorizedResult, register_store_backend\n",
      "  File \"/home/smarton/anaconda3/envs/XAI/lib/python3.8/site-packages/joblib/memory.py\", line 15, in <module>\n",
      "    import pathlib\n",
      "  File \"/home/smarton/anaconda3/envs/XAI/lib/python3.8/pathlib.py\", line 13, in <module>\n",
      "    from urllib.parse import quote_from_bytes as urlquote_from_bytes\n",
      "  File \"<frozen importlib._bootstrap>\", line 991, in _find_and_load\n",
      "  File \"<frozen importlib._bootstrap>\", line 971, in _find_and_load_unlocked\n",
      "  File \"<frozen importlib._bootstrap>\", line 914, in _find_spec\n",
      "  File \"<frozen importlib._bootstrap_external>\", line 1342, in find_spec\n",
      "  File \"<frozen importlib._bootstrap_external>\", line 1314, in _get_spec\n",
      "  File \"<frozen importlib._bootstrap_external>\", line 1458, in find_spec\n",
      "  File \"<frozen importlib._bootstrap_external>\", line 101, in _path_isfile\n",
      "  File \"<frozen importlib._bootstrap_external>\", line 93, in _path_is_mode_type\n",
      "KeyboardInterrupt\n",
      "Traceback (most recent call last):\n",
      "  File \"<frozen importlib._bootstrap_external>\", line 93, in _path_is_mode_type\n",
      "  File \"<frozen importlib._bootstrap_external>\", line 87, in _path_stat\n",
      "FileNotFoundError: [Errno 2] No such file or directory: '/home/smarton/anaconda3/envs/XAI/lib/python3.8/urllib/__init__.cpython-38-x86_64-linux-gnu.so'\n",
      "\n",
      "During handling of the above exception, another exception occurred:\n",
      "\n",
      "Traceback (most recent call last):\n",
      "  File \"/home/smarton/anaconda3/envs/XAI/lib/python3.8/runpy.py\", line 183, in _run_module_as_main\n",
      "    mod_name, mod_spec, code = _get_module_details(mod_name, _Error)\n",
      "  File \"/home/smarton/anaconda3/envs/XAI/lib/python3.8/runpy.py\", line 109, in _get_module_details\n",
      "    __import__(pkg_name)\n",
      "  File \"/home/smarton/anaconda3/envs/XAI/lib/python3.8/site-packages/joblib/__init__.py\", line 113, in <module>\n",
      "    from .memory import Memory, MemorizedResult, register_store_backend\n",
      "  File \"/home/smarton/anaconda3/envs/XAI/lib/python3.8/site-packages/joblib/memory.py\", line 15, in <module>\n",
      "    import pathlib\n",
      "  File \"/home/smarton/anaconda3/envs/XAI/lib/python3.8/pathlib.py\", line 13, in <module>\n",
      "    from urllib.parse import quote_from_bytes as urlquote_from_bytes\n",
      "  File \"<frozen importlib._bootstrap>\", line 991, in _find_and_load\n",
      "  File \"<frozen importlib._bootstrap>\", line 971, in _find_and_load_unlocked\n",
      "  File \"<frozen importlib._bootstrap>\", line 914, in _find_spec\n",
      "  File \"<frozen importlib._bootstrap_external>\", line 1342, in find_spec\n",
      "  File \"<frozen importlib._bootstrap_external>\", line 1314, in _get_spec\n",
      "  File \"<frozen importlib._bootstrap_external>\", line 1458, in find_spec\n",
      "  File \"<frozen importlib._bootstrap_external>\", line 101, in _path_isfile\n",
      "  File \"<frozen importlib._bootstrap_external>\", line 93, in _path_is_mode_type\n",
      "KeyboardInterrupt\n",
      "Traceback (most recent call last):\n",
      "  File \"<frozen importlib._bootstrap_external>\", line 93, in _path_is_mode_type\n",
      "  File \"<frozen importlib._bootstrap_external>\", line 87, in _path_stat\n",
      "FileNotFoundError: [Errno 2] No such file or directory: '/home/smarton/anaconda3/envs/XAI/lib/python3.8/urllib/__init__.cpython-38-x86_64-linux-gnu.so'\n",
      "\n",
      "During handling of the above exception, another exception occurred:\n",
      "\n",
      "Traceback (most recent call last):\n",
      "  File \"/home/smarton/anaconda3/envs/XAI/lib/python3.8/runpy.py\", line 183, in _run_module_as_main\n",
      "    mod_name, mod_spec, code = _get_module_details(mod_name, _Error)\n",
      "  File \"/home/smarton/anaconda3/envs/XAI/lib/python3.8/runpy.py\", line 109, in _get_module_details\n",
      "    __import__(pkg_name)\n",
      "  File \"/home/smarton/anaconda3/envs/XAI/lib/python3.8/site-packages/joblib/__init__.py\", line 113, in <module>\n",
      "    from .memory import Memory, MemorizedResult, register_store_backend\n",
      "  File \"/home/smarton/anaconda3/envs/XAI/lib/python3.8/site-packages/joblib/memory.py\", line 15, in <module>\n",
      "    import pathlib\n",
      "  File \"/home/smarton/anaconda3/envs/XAI/lib/python3.8/pathlib.py\", line 13, in <module>\n",
      "    from urllib.parse import quote_from_bytes as urlquote_from_bytes\n",
      "  File \"<frozen importlib._bootstrap>\", line 991, in _find_and_load\n",
      "  File \"<frozen importlib._bootstrap>\", line 971, in _find_and_load_unlocked\n",
      "  File \"<frozen importlib._bootstrap>\", line 914, in _find_spec\n",
      "  File \"<frozen importlib._bootstrap_external>\", line 1342, in find_spec\n",
      "  File \"<frozen importlib._bootstrap_external>\", line 1314, in _get_spec\n",
      "  File \"<frozen importlib._bootstrap_external>\", line 1458, in find_spec\n",
      "  File \"<frozen importlib._bootstrap_external>\", line 101, in _path_isfile\n",
      "  File \"<frozen importlib._bootstrap_external>\", line 93, in _path_is_mode_type\n",
      "KeyboardInterrupt\n",
      "Traceback (most recent call last):\n",
      "  File \"<frozen importlib._bootstrap_external>\", line 93, in _path_is_mode_type\n",
      "  File \"<frozen importlib._bootstrap_external>\", line 87, in _path_stat\n",
      "FileNotFoundError: [Errno 2] No such file or directory: '/home/smarton/anaconda3/envs/XAI/lib/python3.8/urllib/__init__.cpython-38-x86_64-linux-gnu.so'\n",
      "\n",
      "During handling of the above exception, another exception occurred:\n",
      "\n",
      "Traceback (most recent call last):\n",
      "  File \"/home/smarton/anaconda3/envs/XAI/lib/python3.8/runpy.py\", line 183, in _run_module_as_main\n",
      "    mod_name, mod_spec, code = _get_module_details(mod_name, _Error)\n",
      "  File \"/home/smarton/anaconda3/envs/XAI/lib/python3.8/runpy.py\", line 109, in _get_module_details\n",
      "    __import__(pkg_name)\n",
      "  File \"/home/smarton/anaconda3/envs/XAI/lib/python3.8/site-packages/joblib/__init__.py\", line 113, in <module>\n",
      "    from .memory import Memory, MemorizedResult, register_store_backend\n",
      "  File \"/home/smarton/anaconda3/envs/XAI/lib/python3.8/site-packages/joblib/memory.py\", line 15, in <module>\n",
      "    import pathlib\n",
      "  File \"/home/smarton/anaconda3/envs/XAI/lib/python3.8/pathlib.py\", line 13, in <module>\n",
      "    from urllib.parse import quote_from_bytes as urlquote_from_bytes\n",
      "  File \"<frozen importlib._bootstrap>\", line 991, in _find_and_load\n",
      "  File \"<frozen importlib._bootstrap>\", line 971, in _find_and_load_unlocked\n",
      "  File \"<frozen importlib._bootstrap>\", line 914, in _find_spec\n",
      "  File \"<frozen importlib._bootstrap_external>\", line 1342, in find_spec\n",
      "  File \"<frozen importlib._bootstrap_external>\", line 1314, in _get_spec\n",
      "  File \"<frozen importlib._bootstrap_external>\", line 1458, in find_spec\n",
      "  File \"<frozen importlib._bootstrap_external>\", line 101, in _path_isfile\n",
      "  File \"<frozen importlib._bootstrap_external>\", line 93, in _path_is_mode_type\n",
      "KeyboardInterrupt\n",
      "Traceback (most recent call last):\n",
      "  File \"<frozen importlib._bootstrap_external>\", line 93, in _path_is_mode_type\n",
      "  File \"<frozen importlib._bootstrap_external>\", line 87, in _path_stat\n",
      "FileNotFoundError: [Errno 2] No such file or directory: '/home/smarton/anaconda3/envs/XAI/lib/python3.8/urllib/__init__.cpython-38-x86_64-linux-gnu.so'\n",
      "\n",
      "During handling of the above exception, another exception occurred:\n",
      "\n",
      "Traceback (most recent call last):\n",
      "  File \"/home/smarton/anaconda3/envs/XAI/lib/python3.8/runpy.py\", line 183, in _run_module_as_main\n",
      "    mod_name, mod_spec, code = _get_module_details(mod_name, _Error)\n",
      "  File \"/home/smarton/anaconda3/envs/XAI/lib/python3.8/runpy.py\", line 109, in _get_module_details\n",
      "    __import__(pkg_name)\n",
      "  File \"/home/smarton/anaconda3/envs/XAI/lib/python3.8/site-packages/joblib/__init__.py\", line 113, in <module>\n",
      "    from .memory import Memory, MemorizedResult, register_store_backend\n",
      "  File \"/home/smarton/anaconda3/envs/XAI/lib/python3.8/site-packages/joblib/memory.py\", line 15, in <module>\n",
      "    import pathlib\n",
      "  File \"/home/smarton/anaconda3/envs/XAI/lib/python3.8/pathlib.py\", line 13, in <module>\n",
      "    from urllib.parse import quote_from_bytes as urlquote_from_bytes\n",
      "  File \"<frozen importlib._bootstrap>\", line 991, in _find_and_load\n",
      "  File \"<frozen importlib._bootstrap>\", line 971, in _find_and_load_unlocked\n",
      "  File \"<frozen importlib._bootstrap>\", line 914, in _find_spec\n",
      "  File \"<frozen importlib._bootstrap_external>\", line 1342, in find_spec\n",
      "  File \"<frozen importlib._bootstrap_external>\", line 1314, in _get_spec\n",
      "  File \"<frozen importlib._bootstrap_external>\", line 1458, in find_spec\n",
      "  File \"<frozen importlib._bootstrap_external>\", line 101, in _path_isfile\n",
      "  File \"<frozen importlib._bootstrap_external>\", line 93, in _path_is_mode_type\n",
      "KeyboardInterrupt\n",
      "Traceback (most recent call last):\n",
      "  File \"<frozen importlib._bootstrap_external>\", line 93, in _path_is_mode_type\n",
      "  File \"<frozen importlib._bootstrap_external>\", line 87, in _path_stat\n",
      "FileNotFoundError: [Errno 2] No such file or directory: '/home/smarton/anaconda3/envs/XAI/lib/python3.8/urllib/__init__.cpython-38-x86_64-linux-gnu.so'\n",
      "\n",
      "During handling of the above exception, another exception occurred:\n",
      "\n",
      "Traceback (most recent call last):\n",
      "  File \"/home/smarton/anaconda3/envs/XAI/lib/python3.8/runpy.py\", line 183, in _run_module_as_main\n",
      "    mod_name, mod_spec, code = _get_module_details(mod_name, _Error)\n",
      "  File \"/home/smarton/anaconda3/envs/XAI/lib/python3.8/runpy.py\", line 109, in _get_module_details\n",
      "    __import__(pkg_name)\n",
      "  File \"/home/smarton/anaconda3/envs/XAI/lib/python3.8/site-packages/joblib/__init__.py\", line 113, in <module>\n",
      "    from .memory import Memory, MemorizedResult, register_store_backend\n",
      "  File \"/home/smarton/anaconda3/envs/XAI/lib/python3.8/site-packages/joblib/memory.py\", line 15, in <module>\n",
      "    import pathlib\n",
      "  File \"/home/smarton/anaconda3/envs/XAI/lib/python3.8/pathlib.py\", line 13, in <module>\n",
      "    from urllib.parse import quote_from_bytes as urlquote_from_bytes\n",
      "  File \"<frozen importlib._bootstrap>\", line 991, in _find_and_load\n",
      "  File \"<frozen importlib._bootstrap>\", line 971, in _find_and_load_unlocked\n",
      "  File \"<frozen importlib._bootstrap>\", line 914, in _find_spec\n",
      "  File \"<frozen importlib._bootstrap_external>\", line 1342, in find_spec\n",
      "  File \"<frozen importlib._bootstrap_external>\", line 1314, in _get_spec\n",
      "  File \"<frozen importlib._bootstrap_external>\", line 1458, in find_spec\n",
      "  File \"<frozen importlib._bootstrap_external>\", line 101, in _path_isfile\n",
      "  File \"<frozen importlib._bootstrap_external>\", line 93, in _path_is_mode_type\n",
      "KeyboardInterrupt\n",
      "Traceback (most recent call last):\n",
      "  File \"<frozen importlib._bootstrap_external>\", line 93, in _path_is_mode_type\n",
      "  File \"<frozen importlib._bootstrap_external>\", line 87, in _path_stat\n",
      "FileNotFoundError: [Errno 2] No such file or directory: '/home/smarton/anaconda3/envs/XAI/lib/python3.8/urllib/__init__.cpython-38-x86_64-linux-gnu.so'\n",
      "\n",
      "During handling of the above exception, another exception occurred:\n",
      "\n",
      "Traceback (most recent call last):\n",
      "  File \"/home/smarton/anaconda3/envs/XAI/lib/python3.8/runpy.py\", line 183, in _run_module_as_main\n",
      "    mod_name, mod_spec, code = _get_module_details(mod_name, _Error)\n",
      "  File \"/home/smarton/anaconda3/envs/XAI/lib/python3.8/runpy.py\", line 109, in _get_module_details\n",
      "    __import__(pkg_name)\n",
      "  File \"/home/smarton/anaconda3/envs/XAI/lib/python3.8/site-packages/joblib/__init__.py\", line 113, in <module>\n",
      "    from .memory import Memory, MemorizedResult, register_store_backend\n",
      "  File \"/home/smarton/anaconda3/envs/XAI/lib/python3.8/site-packages/joblib/memory.py\", line 15, in <module>\n",
      "    import pathlib\n",
      "  File \"/home/smarton/anaconda3/envs/XAI/lib/python3.8/pathlib.py\", line 13, in <module>\n",
      "    from urllib.parse import quote_from_bytes as urlquote_from_bytes\n",
      "  File \"<frozen importlib._bootstrap>\", line 991, in _find_and_load\n",
      "  File \"<frozen importlib._bootstrap>\", line 971, in _find_and_load_unlocked\n",
      "  File \"<frozen importlib._bootstrap>\", line 914, in _find_spec\n",
      "  File \"<frozen importlib._bootstrap_external>\", line 1342, in find_spec\n",
      "  File \"<frozen importlib._bootstrap_external>\", line 1314, in _get_spec\n",
      "  File \"<frozen importlib._bootstrap_external>\", line 1458, in find_spec\n",
      "  File \"<frozen importlib._bootstrap_external>\", line 101, in _path_isfile\n",
      "  File \"<frozen importlib._bootstrap_external>\", line 93, in _path_is_mode_type\n",
      "KeyboardInterrupt\n",
      "Traceback (most recent call last):\n",
      "  File \"<frozen importlib._bootstrap_external>\", line 93, in _path_is_mode_type\n",
      "  File \"<frozen importlib._bootstrap_external>\", line 87, in _path_stat\n",
      "FileNotFoundError: [Errno 2] No such file or directory: '/home/smarton/anaconda3/envs/XAI/lib/python3.8/urllib/__init__.cpython-38-x86_64-linux-gnu.so'\n",
      "\n",
      "During handling of the above exception, another exception occurred:\n",
      "\n",
      "Traceback (most recent call last):\n",
      "  File \"/home/smarton/anaconda3/envs/XAI/lib/python3.8/runpy.py\", line 183, in _run_module_as_main\n",
      "    mod_name, mod_spec, code = _get_module_details(mod_name, _Error)\n",
      "  File \"/home/smarton/anaconda3/envs/XAI/lib/python3.8/runpy.py\", line 109, in _get_module_details\n",
      "    __import__(pkg_name)\n",
      "  File \"/home/smarton/anaconda3/envs/XAI/lib/python3.8/site-packages/joblib/__init__.py\", line 113, in <module>\n",
      "    from .memory import Memory, MemorizedResult, register_store_backend\n",
      "  File \"/home/smarton/anaconda3/envs/XAI/lib/python3.8/site-packages/joblib/memory.py\", line 15, in <module>\n",
      "    import pathlib\n",
      "  File \"/home/smarton/anaconda3/envs/XAI/lib/python3.8/pathlib.py\", line 13, in <module>\n",
      "    from urllib.parse import quote_from_bytes as urlquote_from_bytes\n",
      "  File \"<frozen importlib._bootstrap>\", line 991, in _find_and_load\n",
      "  File \"<frozen importlib._bootstrap>\", line 971, in _find_and_load_unlocked\n",
      "  File \"<frozen importlib._bootstrap>\", line 914, in _find_spec\n",
      "  File \"<frozen importlib._bootstrap_external>\", line 1342, in find_spec\n",
      "  File \"<frozen importlib._bootstrap_external>\", line 1314, in _get_spec\n",
      "  File \"<frozen importlib._bootstrap_external>\", line 1458, in find_spec\n",
      "  File \"<frozen importlib._bootstrap_external>\", line 101, in _path_isfile\n",
      "  File \"<frozen importlib._bootstrap_external>\", line 93, in _path_is_mode_type\n",
      "KeyboardInterrupt\n",
      "Traceback (most recent call last):\n",
      "  File \"<frozen importlib._bootstrap_external>\", line 93, in _path_is_mode_type\n",
      "  File \"<frozen importlib._bootstrap_external>\", line 87, in _path_stat\n",
      "FileNotFoundError: [Errno 2] No such file or directory: '/home/smarton/anaconda3/envs/XAI/lib/python3.8/urllib/__init__.cpython-38-x86_64-linux-gnu.so'\n",
      "\n",
      "During handling of the above exception, another exception occurred:\n",
      "\n",
      "Traceback (most recent call last):\n",
      "  File \"/home/smarton/anaconda3/envs/XAI/lib/python3.8/runpy.py\", line 183, in _run_module_as_main\n",
      "    mod_name, mod_spec, code = _get_module_details(mod_name, _Error)\n",
      "  File \"/home/smarton/anaconda3/envs/XAI/lib/python3.8/runpy.py\", line 109, in _get_module_details\n",
      "    __import__(pkg_name)\n",
      "  File \"/home/smarton/anaconda3/envs/XAI/lib/python3.8/site-packages/joblib/__init__.py\", line 113, in <module>\n",
      "    from .memory import Memory, MemorizedResult, register_store_backend\n",
      "  File \"/home/smarton/anaconda3/envs/XAI/lib/python3.8/site-packages/joblib/memory.py\", line 15, in <module>\n",
      "    import pathlib\n",
      "  File \"/home/smarton/anaconda3/envs/XAI/lib/python3.8/pathlib.py\", line 13, in <module>\n",
      "    from urllib.parse import quote_from_bytes as urlquote_from_bytes\n",
      "  File \"<frozen importlib._bootstrap>\", line 991, in _find_and_load\n",
      "  File \"<frozen importlib._bootstrap>\", line 971, in _find_and_load_unlocked\n",
      "  File \"<frozen importlib._bootstrap>\", line 914, in _find_spec\n",
      "  File \"<frozen importlib._bootstrap_external>\", line 1342, in find_spec\n",
      "  File \"<frozen importlib._bootstrap_external>\", line 1314, in _get_spec\n",
      "  File \"<frozen importlib._bootstrap_external>\", line 1458, in find_spec\n",
      "  File \"<frozen importlib._bootstrap_external>\", line 101, in _path_isfile\n",
      "  File \"<frozen importlib._bootstrap_external>\", line 93, in _path_is_mode_type\n",
      "KeyboardInterrupt\n",
      "Traceback (most recent call last):\n",
      "  File \"<frozen importlib._bootstrap_external>\", line 93, in _path_is_mode_type\n",
      "  File \"<frozen importlib._bootstrap_external>\", line 87, in _path_stat\n",
      "FileNotFoundError: [Errno 2] No such file or directory: '/home/smarton/anaconda3/envs/XAI/lib/python3.8/urllib/__init__.cpython-38-x86_64-linux-gnu.so'\n",
      "\n",
      "During handling of the above exception, another exception occurred:\n",
      "\n",
      "Traceback (most recent call last):\n",
      "  File \"/home/smarton/anaconda3/envs/XAI/lib/python3.8/runpy.py\", line 183, in _run_module_as_main\n",
      "    mod_name, mod_spec, code = _get_module_details(mod_name, _Error)\n",
      "  File \"/home/smarton/anaconda3/envs/XAI/lib/python3.8/runpy.py\", line 109, in _get_module_details\n",
      "    __import__(pkg_name)\n",
      "  File \"/home/smarton/anaconda3/envs/XAI/lib/python3.8/site-packages/joblib/__init__.py\", line 113, in <module>\n",
      "    from .memory import Memory, MemorizedResult, register_store_backend\n",
      "  File \"/home/smarton/anaconda3/envs/XAI/lib/python3.8/site-packages/joblib/memory.py\", line 15, in <module>\n",
      "    import pathlib\n",
      "  File \"/home/smarton/anaconda3/envs/XAI/lib/python3.8/pathlib.py\", line 13, in <module>\n",
      "    from urllib.parse import quote_from_bytes as urlquote_from_bytes\n",
      "  File \"<frozen importlib._bootstrap>\", line 991, in _find_and_load\n",
      "  File \"<frozen importlib._bootstrap>\", line 971, in _find_and_load_unlocked\n",
      "  File \"<frozen importlib._bootstrap>\", line 914, in _find_spec\n",
      "  File \"<frozen importlib._bootstrap_external>\", line 1342, in find_spec\n",
      "  File \"<frozen importlib._bootstrap_external>\", line 1314, in _get_spec\n",
      "  File \"<frozen importlib._bootstrap_external>\", line 1458, in find_spec\n",
      "  File \"<frozen importlib._bootstrap_external>\", line 101, in _path_isfile\n",
      "  File \"<frozen importlib._bootstrap_external>\", line 93, in _path_is_mode_type\n",
      "KeyboardInterrupt\n",
      "Traceback (most recent call last):\n",
      "  File \"<frozen importlib._bootstrap_external>\", line 93, in _path_is_mode_type\n",
      "  File \"<frozen importlib._bootstrap_external>\", line 87, in _path_stat\n",
      "FileNotFoundError: [Errno 2] No such file or directory: '/home/smarton/anaconda3/envs/XAI/lib/python3.8/urllib/__init__.cpython-38-x86_64-linux-gnu.so'\n",
      "\n",
      "During handling of the above exception, another exception occurred:\n",
      "\n",
      "Traceback (most recent call last):\n",
      "  File \"/home/smarton/anaconda3/envs/XAI/lib/python3.8/runpy.py\", line 183, in _run_module_as_main\n",
      "    mod_name, mod_spec, code = _get_module_details(mod_name, _Error)\n",
      "  File \"/home/smarton/anaconda3/envs/XAI/lib/python3.8/runpy.py\", line 109, in _get_module_details\n",
      "    __import__(pkg_name)\n",
      "  File \"/home/smarton/anaconda3/envs/XAI/lib/python3.8/site-packages/joblib/__init__.py\", line 113, in <module>\n",
      "    from .memory import Memory, MemorizedResult, register_store_backend\n",
      "  File \"/home/smarton/anaconda3/envs/XAI/lib/python3.8/site-packages/joblib/memory.py\", line 15, in <module>\n",
      "    import pathlib\n",
      "  File \"/home/smarton/anaconda3/envs/XAI/lib/python3.8/pathlib.py\", line 13, in <module>\n",
      "    from urllib.parse import quote_from_bytes as urlquote_from_bytes\n",
      "  File \"<frozen importlib._bootstrap>\", line 991, in _find_and_load\n",
      "  File \"<frozen importlib._bootstrap>\", line 971, in _find_and_load_unlocked\n",
      "  File \"<frozen importlib._bootstrap>\", line 914, in _find_spec\n",
      "  File \"<frozen importlib._bootstrap_external>\", line 1342, in find_spec\n",
      "  File \"<frozen importlib._bootstrap_external>\", line 1314, in _get_spec\n",
      "  File \"<frozen importlib._bootstrap_external>\", line 1458, in find_spec\n",
      "  File \"<frozen importlib._bootstrap_external>\", line 101, in _path_isfile\n",
      "  File \"<frozen importlib._bootstrap_external>\", line 93, in _path_is_mode_type\n",
      "KeyboardInterrupt\n",
      "Traceback (most recent call last):\n",
      "  File \"<frozen importlib._bootstrap_external>\", line 93, in _path_is_mode_type\n",
      "  File \"<frozen importlib._bootstrap_external>\", line 87, in _path_stat\n",
      "FileNotFoundError: [Errno 2] No such file or directory: '/home/smarton/anaconda3/envs/XAI/lib/python3.8/urllib/__init__.cpython-38-x86_64-linux-gnu.so'\n",
      "\n",
      "During handling of the above exception, another exception occurred:\n",
      "\n",
      "Traceback (most recent call last):\n",
      "  File \"/home/smarton/anaconda3/envs/XAI/lib/python3.8/runpy.py\", line 183, in _run_module_as_main\n",
      "    mod_name, mod_spec, code = _get_module_details(mod_name, _Error)\n",
      "  File \"/home/smarton/anaconda3/envs/XAI/lib/python3.8/runpy.py\", line 109, in _get_module_details\n",
      "    __import__(pkg_name)\n",
      "  File \"/home/smarton/anaconda3/envs/XAI/lib/python3.8/site-packages/joblib/__init__.py\", line 113, in <module>\n",
      "    from .memory import Memory, MemorizedResult, register_store_backend\n",
      "  File \"/home/smarton/anaconda3/envs/XAI/lib/python3.8/site-packages/joblib/memory.py\", line 15, in <module>\n",
      "    import pathlib\n",
      "  File \"/home/smarton/anaconda3/envs/XAI/lib/python3.8/pathlib.py\", line 13, in <module>\n",
      "    from urllib.parse import quote_from_bytes as urlquote_from_bytes\n",
      "  File \"<frozen importlib._bootstrap>\", line 991, in _find_and_load\n",
      "  File \"<frozen importlib._bootstrap>\", line 971, in _find_and_load_unlocked\n",
      "  File \"<frozen importlib._bootstrap>\", line 914, in _find_spec\n",
      "  File \"<frozen importlib._bootstrap_external>\", line 1342, in find_spec\n",
      "  File \"<frozen importlib._bootstrap_external>\", line 1314, in _get_spec\n",
      "  File \"<frozen importlib._bootstrap_external>\", line 1458, in find_spec\n",
      "  File \"<frozen importlib._bootstrap_external>\", line 101, in _path_isfile\n",
      "  File \"<frozen importlib._bootstrap_external>\", line 93, in _path_is_mode_type\n",
      "KeyboardInterrupt\n",
      "Traceback (most recent call last):\n",
      "  File \"<frozen importlib._bootstrap_external>\", line 93, in _path_is_mode_type\n",
      "  File \"<frozen importlib._bootstrap_external>\", line 87, in _path_stat\n",
      "FileNotFoundError: [Errno 2] No such file or directory: '/home/smarton/anaconda3/envs/XAI/lib/python3.8/urllib/__init__.cpython-38-x86_64-linux-gnu.so'\n",
      "\n",
      "During handling of the above exception, another exception occurred:\n",
      "\n",
      "Traceback (most recent call last):\n",
      "  File \"/home/smarton/anaconda3/envs/XAI/lib/python3.8/runpy.py\", line 183, in _run_module_as_main\n",
      "    mod_name, mod_spec, code = _get_module_details(mod_name, _Error)\n",
      "  File \"/home/smarton/anaconda3/envs/XAI/lib/python3.8/runpy.py\", line 109, in _get_module_details\n",
      "    __import__(pkg_name)\n",
      "  File \"/home/smarton/anaconda3/envs/XAI/lib/python3.8/site-packages/joblib/__init__.py\", line 113, in <module>\n",
      "    from .memory import Memory, MemorizedResult, register_store_backend\n",
      "  File \"/home/smarton/anaconda3/envs/XAI/lib/python3.8/site-packages/joblib/memory.py\", line 15, in <module>\n",
      "    import pathlib\n",
      "  File \"/home/smarton/anaconda3/envs/XAI/lib/python3.8/pathlib.py\", line 13, in <module>\n",
      "    from urllib.parse import quote_from_bytes as urlquote_from_bytes\n",
      "  File \"<frozen importlib._bootstrap>\", line 991, in _find_and_load\n",
      "  File \"<frozen importlib._bootstrap>\", line 971, in _find_and_load_unlocked\n",
      "  File \"<frozen importlib._bootstrap>\", line 914, in _find_spec\n",
      "  File \"<frozen importlib._bootstrap_external>\", line 1342, in find_spec\n",
      "  File \"<frozen importlib._bootstrap_external>\", line 1314, in _get_spec\n",
      "  File \"<frozen importlib._bootstrap_external>\", line 1458, in find_spec\n",
      "  File \"<frozen importlib._bootstrap_external>\", line 101, in _path_isfile\n",
      "  File \"<frozen importlib._bootstrap_external>\", line 93, in _path_is_mode_type\n",
      "KeyboardInterrupt\n",
      "Traceback (most recent call last):\n",
      "  File \"<frozen importlib._bootstrap_external>\", line 93, in _path_is_mode_type\n",
      "  File \"<frozen importlib._bootstrap_external>\", line 87, in _path_stat\n",
      "FileNotFoundError: [Errno 2] No such file or directory: '/home/smarton/anaconda3/envs/XAI/lib/python3.8/urllib/__init__.cpython-38-x86_64-linux-gnu.so'\n",
      "\n",
      "During handling of the above exception, another exception occurred:\n",
      "\n",
      "Traceback (most recent call last):\n",
      "  File \"/home/smarton/anaconda3/envs/XAI/lib/python3.8/runpy.py\", line 183, in _run_module_as_main\n",
      "    mod_name, mod_spec, code = _get_module_details(mod_name, _Error)\n",
      "  File \"/home/smarton/anaconda3/envs/XAI/lib/python3.8/runpy.py\", line 109, in _get_module_details\n",
      "    __import__(pkg_name)\n",
      "  File \"/home/smarton/anaconda3/envs/XAI/lib/python3.8/site-packages/joblib/__init__.py\", line 113, in <module>\n",
      "    from .memory import Memory, MemorizedResult, register_store_backend\n",
      "  File \"/home/smarton/anaconda3/envs/XAI/lib/python3.8/site-packages/joblib/memory.py\", line 15, in <module>\n",
      "    import pathlib\n",
      "  File \"/home/smarton/anaconda3/envs/XAI/lib/python3.8/pathlib.py\", line 13, in <module>\n",
      "    from urllib.parse import quote_from_bytes as urlquote_from_bytes\n",
      "  File \"<frozen importlib._bootstrap>\", line 991, in _find_and_load\n",
      "  File \"<frozen importlib._bootstrap>\", line 971, in _find_and_load_unlocked\n",
      "  File \"<frozen importlib._bootstrap>\", line 914, in _find_spec\n",
      "  File \"<frozen importlib._bootstrap_external>\", line 1342, in find_spec\n",
      "  File \"<frozen importlib._bootstrap_external>\", line 1314, in _get_spec\n",
      "  File \"<frozen importlib._bootstrap_external>\", line 1458, in find_spec\n",
      "  File \"<frozen importlib._bootstrap_external>\", line 101, in _path_isfile\n",
      "  File \"<frozen importlib._bootstrap_external>\", line 93, in _path_is_mode_type\n",
      "KeyboardInterrupt\n",
      "Traceback (most recent call last):\n",
      "  File \"<frozen importlib._bootstrap_external>\", line 93, in _path_is_mode_type\n",
      "  File \"<frozen importlib._bootstrap_external>\", line 87, in _path_stat\n",
      "FileNotFoundError: [Errno 2] No such file or directory: '/home/smarton/anaconda3/envs/XAI/lib/python3.8/urllib/__init__.cpython-38-x86_64-linux-gnu.so'\n",
      "\n",
      "During handling of the above exception, another exception occurred:\n",
      "\n",
      "Traceback (most recent call last):\n",
      "  File \"/home/smarton/anaconda3/envs/XAI/lib/python3.8/runpy.py\", line 183, in _run_module_as_main\n",
      "    mod_name, mod_spec, code = _get_module_details(mod_name, _Error)\n",
      "  File \"/home/smarton/anaconda3/envs/XAI/lib/python3.8/runpy.py\", line 109, in _get_module_details\n",
      "    __import__(pkg_name)\n",
      "  File \"/home/smarton/anaconda3/envs/XAI/lib/python3.8/site-packages/joblib/__init__.py\", line 113, in <module>\n",
      "    from .memory import Memory, MemorizedResult, register_store_backend\n",
      "  File \"/home/smarton/anaconda3/envs/XAI/lib/python3.8/site-packages/joblib/memory.py\", line 15, in <module>\n",
      "    import pathlib\n",
      "  File \"/home/smarton/anaconda3/envs/XAI/lib/python3.8/pathlib.py\", line 13, in <module>\n",
      "    from urllib.parse import quote_from_bytes as urlquote_from_bytes\n",
      "  File \"<frozen importlib._bootstrap>\", line 991, in _find_and_load\n",
      "  File \"<frozen importlib._bootstrap>\", line 971, in _find_and_load_unlocked\n",
      "  File \"<frozen importlib._bootstrap>\", line 914, in _find_spec\n",
      "  File \"<frozen importlib._bootstrap_external>\", line 1342, in find_spec\n",
      "  File \"<frozen importlib._bootstrap_external>\", line 1314, in _get_spec\n",
      "  File \"<frozen importlib._bootstrap_external>\", line 1458, in find_spec\n",
      "  File \"<frozen importlib._bootstrap_external>\", line 101, in _path_isfile\n",
      "  File \"<frozen importlib._bootstrap_external>\", line 93, in _path_is_mode_type\n",
      "KeyboardInterrupt\n",
      "Traceback (most recent call last):\n",
      "  File \"<frozen importlib._bootstrap_external>\", line 93, in _path_is_mode_type\n",
      "  File \"<frozen importlib._bootstrap_external>\", line 87, in _path_stat\n",
      "FileNotFoundError: [Errno 2] No such file or directory: '/home/smarton/anaconda3/envs/XAI/lib/python3.8/urllib/__init__.cpython-38-x86_64-linux-gnu.so'\n",
      "\n",
      "During handling of the above exception, another exception occurred:\n",
      "\n",
      "Traceback (most recent call last):\n",
      "  File \"/home/smarton/anaconda3/envs/XAI/lib/python3.8/runpy.py\", line 183, in _run_module_as_main\n",
      "    mod_name, mod_spec, code = _get_module_details(mod_name, _Error)\n",
      "  File \"/home/smarton/anaconda3/envs/XAI/lib/python3.8/runpy.py\", line 109, in _get_module_details\n",
      "    __import__(pkg_name)\n",
      "  File \"/home/smarton/anaconda3/envs/XAI/lib/python3.8/site-packages/joblib/__init__.py\", line 113, in <module>\n",
      "    from .memory import Memory, MemorizedResult, register_store_backend\n",
      "  File \"/home/smarton/anaconda3/envs/XAI/lib/python3.8/site-packages/joblib/memory.py\", line 15, in <module>\n",
      "    import pathlib\n",
      "  File \"/home/smarton/anaconda3/envs/XAI/lib/python3.8/pathlib.py\", line 13, in <module>\n",
      "    from urllib.parse import quote_from_bytes as urlquote_from_bytes\n",
      "  File \"<frozen importlib._bootstrap>\", line 991, in _find_and_load\n",
      "  File \"<frozen importlib._bootstrap>\", line 971, in _find_and_load_unlocked\n",
      "  File \"<frozen importlib._bootstrap>\", line 914, in _find_spec\n",
      "  File \"<frozen importlib._bootstrap_external>\", line 1342, in find_spec\n",
      "  File \"<frozen importlib._bootstrap_external>\", line 1314, in _get_spec\n",
      "  File \"<frozen importlib._bootstrap_external>\", line 1458, in find_spec\n",
      "  File \"<frozen importlib._bootstrap_external>\", line 101, in _path_isfile\n",
      "  File \"<frozen importlib._bootstrap_external>\", line 93, in _path_is_mode_type\n",
      "KeyboardInterrupt\n",
      "Traceback (most recent call last):\n",
      "  File \"<frozen importlib._bootstrap_external>\", line 93, in _path_is_mode_type\n",
      "  File \"<frozen importlib._bootstrap_external>\", line 87, in _path_stat\n",
      "FileNotFoundError: [Errno 2] No such file or directory: '/home/smarton/anaconda3/envs/XAI/lib/python3.8/urllib/__init__.cpython-38-x86_64-linux-gnu.so'\n",
      "\n",
      "During handling of the above exception, another exception occurred:\n",
      "\n",
      "Traceback (most recent call last):\n",
      "  File \"/home/smarton/anaconda3/envs/XAI/lib/python3.8/runpy.py\", line 183, in _run_module_as_main\n",
      "    mod_name, mod_spec, code = _get_module_details(mod_name, _Error)\n",
      "  File \"/home/smarton/anaconda3/envs/XAI/lib/python3.8/runpy.py\", line 109, in _get_module_details\n",
      "    __import__(pkg_name)\n",
      "  File \"/home/smarton/anaconda3/envs/XAI/lib/python3.8/site-packages/joblib/__init__.py\", line 113, in <module>\n",
      "    from .memory import Memory, MemorizedResult, register_store_backend\n",
      "  File \"/home/smarton/anaconda3/envs/XAI/lib/python3.8/site-packages/joblib/memory.py\", line 15, in <module>\n",
      "    import pathlib\n",
      "  File \"/home/smarton/anaconda3/envs/XAI/lib/python3.8/pathlib.py\", line 13, in <module>\n",
      "    from urllib.parse import quote_from_bytes as urlquote_from_bytes\n",
      "  File \"<frozen importlib._bootstrap>\", line 991, in _find_and_load\n",
      "  File \"<frozen importlib._bootstrap>\", line 971, in _find_and_load_unlocked\n",
      "  File \"<frozen importlib._bootstrap>\", line 914, in _find_spec\n",
      "  File \"<frozen importlib._bootstrap_external>\", line 1342, in find_spec\n",
      "  File \"<frozen importlib._bootstrap_external>\", line 1314, in _get_spec\n",
      "  File \"<frozen importlib._bootstrap_external>\", line 1458, in find_spec\n",
      "  File \"<frozen importlib._bootstrap_external>\", line 101, in _path_isfile\n",
      "  File \"<frozen importlib._bootstrap_external>\", line 93, in _path_is_mode_type\n",
      "KeyboardInterrupt\n",
      "Traceback (most recent call last):\n",
      "  File \"<frozen importlib._bootstrap_external>\", line 93, in _path_is_mode_type\n",
      "  File \"<frozen importlib._bootstrap_external>\", line 87, in _path_stat\n",
      "FileNotFoundError: [Errno 2] No such file or directory: '/home/smarton/anaconda3/envs/XAI/lib/python3.8/urllib/__init__.cpython-38-x86_64-linux-gnu.so'\n",
      "\n",
      "During handling of the above exception, another exception occurred:\n",
      "\n",
      "Traceback (most recent call last):\n",
      "  File \"/home/smarton/anaconda3/envs/XAI/lib/python3.8/runpy.py\", line 183, in _run_module_as_main\n",
      "    mod_name, mod_spec, code = _get_module_details(mod_name, _Error)\n",
      "  File \"/home/smarton/anaconda3/envs/XAI/lib/python3.8/runpy.py\", line 109, in _get_module_details\n",
      "    __import__(pkg_name)\n",
      "  File \"/home/smarton/anaconda3/envs/XAI/lib/python3.8/site-packages/joblib/__init__.py\", line 113, in <module>\n",
      "    from .memory import Memory, MemorizedResult, register_store_backend\n",
      "  File \"/home/smarton/anaconda3/envs/XAI/lib/python3.8/site-packages/joblib/memory.py\", line 15, in <module>\n",
      "    import pathlib\n",
      "  File \"/home/smarton/anaconda3/envs/XAI/lib/python3.8/pathlib.py\", line 13, in <module>\n",
      "    from urllib.parse import quote_from_bytes as urlquote_from_bytes\n",
      "  File \"<frozen importlib._bootstrap>\", line 991, in _find_and_load\n",
      "  File \"<frozen importlib._bootstrap>\", line 971, in _find_and_load_unlocked\n",
      "  File \"<frozen importlib._bootstrap>\", line 914, in _find_spec\n",
      "  File \"<frozen importlib._bootstrap_external>\", line 1342, in find_spec\n",
      "  File \"<frozen importlib._bootstrap_external>\", line 1314, in _get_spec\n",
      "  File \"<frozen importlib._bootstrap_external>\", line 1458, in find_spec\n",
      "  File \"<frozen importlib._bootstrap_external>\", line 101, in _path_isfile\n",
      "  File \"<frozen importlib._bootstrap_external>\", line 93, in _path_is_mode_type\n",
      "KeyboardInterrupt\n",
      "Traceback (most recent call last):\n",
      "  File \"<frozen importlib._bootstrap_external>\", line 93, in _path_is_mode_type\n",
      "  File \"<frozen importlib._bootstrap_external>\", line 87, in _path_stat\n",
      "FileNotFoundError: [Errno 2] No such file or directory: '/home/smarton/anaconda3/envs/XAI/lib/python3.8/urllib/__init__.cpython-38-x86_64-linux-gnu.so'\n",
      "\n",
      "During handling of the above exception, another exception occurred:\n",
      "\n",
      "Traceback (most recent call last):\n",
      "  File \"/home/smarton/anaconda3/envs/XAI/lib/python3.8/runpy.py\", line 183, in _run_module_as_main\n",
      "    mod_name, mod_spec, code = _get_module_details(mod_name, _Error)\n",
      "  File \"/home/smarton/anaconda3/envs/XAI/lib/python3.8/runpy.py\", line 109, in _get_module_details\n",
      "    __import__(pkg_name)\n",
      "  File \"/home/smarton/anaconda3/envs/XAI/lib/python3.8/site-packages/joblib/__init__.py\", line 113, in <module>\n",
      "    from .memory import Memory, MemorizedResult, register_store_backend\n",
      "  File \"/home/smarton/anaconda3/envs/XAI/lib/python3.8/site-packages/joblib/memory.py\", line 15, in <module>\n",
      "    import pathlib\n",
      "  File \"/home/smarton/anaconda3/envs/XAI/lib/python3.8/pathlib.py\", line 13, in <module>\n",
      "    from urllib.parse import quote_from_bytes as urlquote_from_bytes\n",
      "  File \"<frozen importlib._bootstrap>\", line 991, in _find_and_load\n",
      "  File \"<frozen importlib._bootstrap>\", line 971, in _find_and_load_unlocked\n",
      "  File \"<frozen importlib._bootstrap>\", line 914, in _find_spec\n",
      "  File \"<frozen importlib._bootstrap_external>\", line 1342, in find_spec\n",
      "  File \"<frozen importlib._bootstrap_external>\", line 1314, in _get_spec\n",
      "  File \"<frozen importlib._bootstrap_external>\", line 1458, in find_spec\n",
      "  File \"<frozen importlib._bootstrap_external>\", line 101, in _path_isfile\n",
      "  File \"<frozen importlib._bootstrap_external>\", line 93, in _path_is_mode_type\n",
      "KeyboardInterrupt\n",
      "ERROR:root:Internal Python error in the inspect module.\n",
      "Below is the traceback from this internal error.\n",
      "\n"
     ]
    },
    {
     "name": "stdout",
     "output_type": "stream",
     "text": [
      "Traceback (most recent call last):\n",
      "  File \"/home/smarton/anaconda3/envs/XAI/lib/python3.8/site-packages/IPython/core/interactiveshell.py\", line 3441, in run_code\n",
      "    exec(code_obj, self.user_global_ns, self.user_ns)\n",
      "  File \"/tmp/ipykernel_2570642/1427022256.py\", line 3, in <module>\n",
      "    evaluation_results_hpo_synthetic = parallel_hpo_synthetic(delayed(evaluate_parameter_setting_synthetic)(parameter_setting, config, metrics= ['accuracy', 'f1']) for parameter_setting in parameter_grid)\n",
      "  File \"/home/smarton/anaconda3/envs/XAI/lib/python3.8/site-packages/joblib/parallel.py\", line 1054, in __call__\n",
      "    self.retrieve()\n",
      "  File \"/home/smarton/anaconda3/envs/XAI/lib/python3.8/site-packages/joblib/parallel.py\", line 933, in retrieve\n",
      "    self._output.extend(job.get(timeout=self.timeout))\n",
      "  File \"/home/smarton/anaconda3/envs/XAI/lib/python3.8/site-packages/joblib/_parallel_backends.py\", line 542, in wrap_future_result\n",
      "    return future.result(timeout=timeout)\n",
      "  File \"/home/smarton/anaconda3/envs/XAI/lib/python3.8/concurrent/futures/_base.py\", line 434, in result\n",
      "    self._condition.wait(timeout)\n",
      "  File \"/home/smarton/anaconda3/envs/XAI/lib/python3.8/threading.py\", line 302, in wait\n",
      "    waiter.acquire()\n",
      "KeyboardInterrupt\n",
      "\n",
      "During handling of the above exception, another exception occurred:\n",
      "\n",
      "Traceback (most recent call last):\n",
      "  File \"/home/smarton/anaconda3/envs/XAI/lib/python3.8/site-packages/IPython/core/interactiveshell.py\", line 2061, in showtraceback\n",
      "    stb = value._render_traceback_()\n",
      "AttributeError: 'KeyboardInterrupt' object has no attribute '_render_traceback_'\n",
      "\n",
      "During handling of the above exception, another exception occurred:\n",
      "\n",
      "Traceback (most recent call last):\n",
      "  File \"/home/smarton/anaconda3/envs/XAI/lib/python3.8/site-packages/IPython/core/ultratb.py\", line 1101, in get_records\n",
      "    return _fixed_getinnerframes(etb, number_of_lines_of_context, tb_offset)\n",
      "  File \"/home/smarton/anaconda3/envs/XAI/lib/python3.8/site-packages/IPython/core/ultratb.py\", line 248, in wrapped\n",
      "    return f(*args, **kwargs)\n",
      "  File \"/home/smarton/anaconda3/envs/XAI/lib/python3.8/site-packages/IPython/core/ultratb.py\", line 281, in _fixed_getinnerframes\n",
      "    records = fix_frame_records_filenames(inspect.getinnerframes(etb, context))\n",
      "  File \"/home/smarton/anaconda3/envs/XAI/lib/python3.8/inspect.py\", line 1503, in getinnerframes\n",
      "    frameinfo = (tb.tb_frame,) + getframeinfo(tb, context)\n",
      "  File \"/home/smarton/anaconda3/envs/XAI/lib/python3.8/inspect.py\", line 1461, in getframeinfo\n",
      "    filename = getsourcefile(frame) or getfile(frame)\n",
      "  File \"/home/smarton/anaconda3/envs/XAI/lib/python3.8/inspect.py\", line 708, in getsourcefile\n",
      "    if getattr(getmodule(object, filename), '__loader__', None) is not None:\n",
      "  File \"/home/smarton/anaconda3/envs/XAI/lib/python3.8/inspect.py\", line 751, in getmodule\n",
      "    f = getabsfile(module)\n",
      "  File \"/home/smarton/anaconda3/envs/XAI/lib/python3.8/inspect.py\", line 720, in getabsfile\n",
      "    _filename = getsourcefile(object) or getfile(object)\n",
      "  File \"/home/smarton/anaconda3/envs/XAI/lib/python3.8/inspect.py\", line 705, in getsourcefile\n",
      "    if os.path.exists(filename):\n",
      "  File \"/home/smarton/anaconda3/envs/XAI/lib/python3.8/genericpath.py\", line 19, in exists\n",
      "    os.stat(path)\n",
      "KeyboardInterrupt\n"
     ]
    },
    {
     "name": "stderr",
     "output_type": "stream",
     "text": [
      "ERROR:root:Internal Python error in the inspect module.\n",
      "Below is the traceback from this internal error.\n",
      "\n"
     ]
    },
    {
     "name": "stdout",
     "output_type": "stream",
     "text": [
      "Traceback (most recent call last):\n",
      "  File \"/home/smarton/anaconda3/envs/XAI/lib/python3.8/site-packages/IPython/core/interactiveshell.py\", line 3441, in run_code\n",
      "    exec(code_obj, self.user_global_ns, self.user_ns)\n",
      "  File \"/tmp/ipykernel_2570642/1427022256.py\", line 3, in <module>\n",
      "    evaluation_results_hpo_synthetic = parallel_hpo_synthetic(delayed(evaluate_parameter_setting_synthetic)(parameter_setting, config, metrics= ['accuracy', 'f1']) for parameter_setting in parameter_grid)\n",
      "  File \"/home/smarton/anaconda3/envs/XAI/lib/python3.8/site-packages/joblib/parallel.py\", line 1054, in __call__\n",
      "    self.retrieve()\n",
      "  File \"/home/smarton/anaconda3/envs/XAI/lib/python3.8/site-packages/joblib/parallel.py\", line 933, in retrieve\n",
      "    self._output.extend(job.get(timeout=self.timeout))\n",
      "  File \"/home/smarton/anaconda3/envs/XAI/lib/python3.8/site-packages/joblib/_parallel_backends.py\", line 542, in wrap_future_result\n",
      "    return future.result(timeout=timeout)\n",
      "  File \"/home/smarton/anaconda3/envs/XAI/lib/python3.8/concurrent/futures/_base.py\", line 434, in result\n",
      "    self._condition.wait(timeout)\n",
      "  File \"/home/smarton/anaconda3/envs/XAI/lib/python3.8/threading.py\", line 302, in wait\n",
      "    waiter.acquire()\n",
      "KeyboardInterrupt\n",
      "\n",
      "During handling of the above exception, another exception occurred:\n",
      "\n",
      "Traceback (most recent call last):\n",
      "  File \"/home/smarton/anaconda3/envs/XAI/lib/python3.8/site-packages/IPython/core/interactiveshell.py\", line 2061, in showtraceback\n",
      "    stb = value._render_traceback_()\n",
      "AttributeError: 'KeyboardInterrupt' object has no attribute '_render_traceback_'\n",
      "\n",
      "During handling of the above exception, another exception occurred:\n",
      "\n",
      "Traceback (most recent call last):\n",
      "  File \"/home/smarton/anaconda3/envs/XAI/lib/python3.8/site-packages/IPython/core/interactiveshell.py\", line 3361, in run_ast_nodes\n",
      "    if (await self.run_code(code, result,  async_=asy)):\n",
      "  File \"/home/smarton/anaconda3/envs/XAI/lib/python3.8/site-packages/IPython/core/interactiveshell.py\", line 3458, in run_code\n",
      "    self.showtraceback(running_compiled_code=True)\n",
      "  File \"/home/smarton/anaconda3/envs/XAI/lib/python3.8/site-packages/IPython/core/interactiveshell.py\", line 2063, in showtraceback\n",
      "    stb = self.InteractiveTB.structured_traceback(etype,\n",
      "  File \"/home/smarton/anaconda3/envs/XAI/lib/python3.8/site-packages/IPython/core/ultratb.py\", line 1367, in structured_traceback\n",
      "    return FormattedTB.structured_traceback(\n",
      "  File \"/home/smarton/anaconda3/envs/XAI/lib/python3.8/site-packages/IPython/core/ultratb.py\", line 1267, in structured_traceback\n",
      "    return VerboseTB.structured_traceback(\n",
      "  File \"/home/smarton/anaconda3/envs/XAI/lib/python3.8/site-packages/IPython/core/ultratb.py\", line 1124, in structured_traceback\n",
      "    formatted_exception = self.format_exception_as_a_whole(etype, evalue, etb, number_of_lines_of_context,\n",
      "  File \"/home/smarton/anaconda3/envs/XAI/lib/python3.8/site-packages/IPython/core/ultratb.py\", line 1082, in format_exception_as_a_whole\n",
      "    last_unique, recursion_repeat = find_recursion(orig_etype, evalue, records)\n",
      "  File \"/home/smarton/anaconda3/envs/XAI/lib/python3.8/site-packages/IPython/core/ultratb.py\", line 382, in find_recursion\n",
      "    return len(records), 0\n",
      "TypeError: object of type 'NoneType' has no len()\n",
      "\n",
      "During handling of the above exception, another exception occurred:\n",
      "\n",
      "Traceback (most recent call last):\n",
      "  File \"/home/smarton/anaconda3/envs/XAI/lib/python3.8/site-packages/IPython/core/interactiveshell.py\", line 2061, in showtraceback\n",
      "    stb = value._render_traceback_()\n",
      "AttributeError: 'TypeError' object has no attribute '_render_traceback_'\n",
      "\n",
      "During handling of the above exception, another exception occurred:\n",
      "\n",
      "Traceback (most recent call last):\n",
      "  File \"/home/smarton/anaconda3/envs/XAI/lib/python3.8/site-packages/IPython/core/ultratb.py\", line 1101, in get_records\n",
      "    return _fixed_getinnerframes(etb, number_of_lines_of_context, tb_offset)\n",
      "  File \"/home/smarton/anaconda3/envs/XAI/lib/python3.8/site-packages/IPython/core/ultratb.py\", line 248, in wrapped\n",
      "    return f(*args, **kwargs)\n",
      "  File \"/home/smarton/anaconda3/envs/XAI/lib/python3.8/site-packages/IPython/core/ultratb.py\", line 281, in _fixed_getinnerframes\n",
      "    records = fix_frame_records_filenames(inspect.getinnerframes(etb, context))\n",
      "  File \"/home/smarton/anaconda3/envs/XAI/lib/python3.8/inspect.py\", line 1503, in getinnerframes\n",
      "    frameinfo = (tb.tb_frame,) + getframeinfo(tb, context)\n",
      "  File \"/home/smarton/anaconda3/envs/XAI/lib/python3.8/inspect.py\", line 1461, in getframeinfo\n",
      "    filename = getsourcefile(frame) or getfile(frame)\n",
      "  File \"/home/smarton/anaconda3/envs/XAI/lib/python3.8/inspect.py\", line 708, in getsourcefile\n",
      "    if getattr(getmodule(object, filename), '__loader__', None) is not None:\n",
      "  File \"/home/smarton/anaconda3/envs/XAI/lib/python3.8/inspect.py\", line 751, in getmodule\n",
      "    f = getabsfile(module)\n",
      "  File \"/home/smarton/anaconda3/envs/XAI/lib/python3.8/inspect.py\", line 720, in getabsfile\n",
      "    _filename = getsourcefile(object) or getfile(object)\n",
      "  File \"/home/smarton/anaconda3/envs/XAI/lib/python3.8/inspect.py\", line 705, in getsourcefile\n",
      "    if os.path.exists(filename):\n",
      "  File \"/home/smarton/anaconda3/envs/XAI/lib/python3.8/genericpath.py\", line 19, in exists\n",
      "    os.stat(path)\n",
      "KeyboardInterrupt\n"
     ]
    },
    {
     "name": "stderr",
     "output_type": "stream",
     "text": [
      "ERROR:root:Internal Python error in the inspect module.\n",
      "Below is the traceback from this internal error.\n",
      "\n"
     ]
    },
    {
     "name": "stdout",
     "output_type": "stream",
     "text": [
      "Traceback (most recent call last):\n",
      "  File \"/home/smarton/anaconda3/envs/XAI/lib/python3.8/site-packages/IPython/core/interactiveshell.py\", line 3441, in run_code\n",
      "    exec(code_obj, self.user_global_ns, self.user_ns)\n",
      "  File \"/tmp/ipykernel_2570642/1427022256.py\", line 3, in <module>\n",
      "    evaluation_results_hpo_synthetic = parallel_hpo_synthetic(delayed(evaluate_parameter_setting_synthetic)(parameter_setting, config, metrics= ['accuracy', 'f1']) for parameter_setting in parameter_grid)\n",
      "  File \"/home/smarton/anaconda3/envs/XAI/lib/python3.8/site-packages/joblib/parallel.py\", line 1054, in __call__\n",
      "    self.retrieve()\n",
      "  File \"/home/smarton/anaconda3/envs/XAI/lib/python3.8/site-packages/joblib/parallel.py\", line 933, in retrieve\n",
      "    self._output.extend(job.get(timeout=self.timeout))\n",
      "  File \"/home/smarton/anaconda3/envs/XAI/lib/python3.8/site-packages/joblib/_parallel_backends.py\", line 542, in wrap_future_result\n",
      "    return future.result(timeout=timeout)\n",
      "  File \"/home/smarton/anaconda3/envs/XAI/lib/python3.8/concurrent/futures/_base.py\", line 434, in result\n",
      "    self._condition.wait(timeout)\n",
      "  File \"/home/smarton/anaconda3/envs/XAI/lib/python3.8/threading.py\", line 302, in wait\n",
      "    waiter.acquire()\n",
      "KeyboardInterrupt\n",
      "\n",
      "During handling of the above exception, another exception occurred:\n",
      "\n",
      "Traceback (most recent call last):\n",
      "  File \"/home/smarton/anaconda3/envs/XAI/lib/python3.8/site-packages/IPython/core/interactiveshell.py\", line 2061, in showtraceback\n",
      "    stb = value._render_traceback_()\n",
      "AttributeError: 'KeyboardInterrupt' object has no attribute '_render_traceback_'\n",
      "\n",
      "During handling of the above exception, another exception occurred:\n",
      "\n",
      "Traceback (most recent call last):\n",
      "  File \"/home/smarton/anaconda3/envs/XAI/lib/python3.8/site-packages/IPython/core/interactiveshell.py\", line 3361, in run_ast_nodes\n",
      "    if (await self.run_code(code, result,  async_=asy)):\n",
      "  File \"/home/smarton/anaconda3/envs/XAI/lib/python3.8/site-packages/IPython/core/interactiveshell.py\", line 3458, in run_code\n",
      "    self.showtraceback(running_compiled_code=True)\n",
      "  File \"/home/smarton/anaconda3/envs/XAI/lib/python3.8/site-packages/IPython/core/interactiveshell.py\", line 2063, in showtraceback\n",
      "    stb = self.InteractiveTB.structured_traceback(etype,\n",
      "  File \"/home/smarton/anaconda3/envs/XAI/lib/python3.8/site-packages/IPython/core/ultratb.py\", line 1367, in structured_traceback\n",
      "    return FormattedTB.structured_traceback(\n",
      "  File \"/home/smarton/anaconda3/envs/XAI/lib/python3.8/site-packages/IPython/core/ultratb.py\", line 1267, in structured_traceback\n",
      "    return VerboseTB.structured_traceback(\n",
      "  File \"/home/smarton/anaconda3/envs/XAI/lib/python3.8/site-packages/IPython/core/ultratb.py\", line 1124, in structured_traceback\n",
      "    formatted_exception = self.format_exception_as_a_whole(etype, evalue, etb, number_of_lines_of_context,\n",
      "  File \"/home/smarton/anaconda3/envs/XAI/lib/python3.8/site-packages/IPython/core/ultratb.py\", line 1082, in format_exception_as_a_whole\n",
      "    last_unique, recursion_repeat = find_recursion(orig_etype, evalue, records)\n",
      "  File \"/home/smarton/anaconda3/envs/XAI/lib/python3.8/site-packages/IPython/core/ultratb.py\", line 382, in find_recursion\n",
      "    return len(records), 0\n",
      "TypeError: object of type 'NoneType' has no len()\n",
      "\n",
      "During handling of the above exception, another exception occurred:\n",
      "\n",
      "Traceback (most recent call last):\n",
      "  File \"/home/smarton/anaconda3/envs/XAI/lib/python3.8/site-packages/IPython/core/interactiveshell.py\", line 2061, in showtraceback\n",
      "    stb = value._render_traceback_()\n",
      "AttributeError: 'TypeError' object has no attribute '_render_traceback_'\n",
      "\n",
      "During handling of the above exception, another exception occurred:\n",
      "\n",
      "Traceback (most recent call last):\n",
      "  File \"/home/smarton/anaconda3/envs/XAI/lib/python3.8/site-packages/IPython/core/interactiveshell.py\", line 2944, in _run_cell\n",
      "    return runner(coro)\n",
      "  File \"/home/smarton/anaconda3/envs/XAI/lib/python3.8/site-packages/IPython/core/async_helpers.py\", line 68, in _pseudo_sync_runner\n",
      "    coro.send(None)\n",
      "  File \"/home/smarton/anaconda3/envs/XAI/lib/python3.8/site-packages/IPython/core/interactiveshell.py\", line 3169, in run_cell_async\n",
      "    has_raised = await self.run_ast_nodes(code_ast.body, cell_name,\n",
      "  File \"/home/smarton/anaconda3/envs/XAI/lib/python3.8/site-packages/IPython/core/interactiveshell.py\", line 3380, in run_ast_nodes\n",
      "    self.showtraceback()\n",
      "  File \"/home/smarton/anaconda3/envs/XAI/lib/python3.8/site-packages/IPython/core/interactiveshell.py\", line 2063, in showtraceback\n",
      "    stb = self.InteractiveTB.structured_traceback(etype,\n",
      "  File \"/home/smarton/anaconda3/envs/XAI/lib/python3.8/site-packages/IPython/core/ultratb.py\", line 1367, in structured_traceback\n",
      "    return FormattedTB.structured_traceback(\n",
      "  File \"/home/smarton/anaconda3/envs/XAI/lib/python3.8/site-packages/IPython/core/ultratb.py\", line 1267, in structured_traceback\n",
      "    return VerboseTB.structured_traceback(\n",
      "  File \"/home/smarton/anaconda3/envs/XAI/lib/python3.8/site-packages/IPython/core/ultratb.py\", line 1142, in structured_traceback\n",
      "    formatted_exceptions += self.format_exception_as_a_whole(etype, evalue, etb, lines_of_context,\n",
      "  File \"/home/smarton/anaconda3/envs/XAI/lib/python3.8/site-packages/IPython/core/ultratb.py\", line 1082, in format_exception_as_a_whole\n",
      "    last_unique, recursion_repeat = find_recursion(orig_etype, evalue, records)\n",
      "  File \"/home/smarton/anaconda3/envs/XAI/lib/python3.8/site-packages/IPython/core/ultratb.py\", line 382, in find_recursion\n",
      "    return len(records), 0\n",
      "TypeError: object of type 'NoneType' has no len()\n",
      "\n",
      "During handling of the above exception, another exception occurred:\n",
      "\n",
      "Traceback (most recent call last):\n",
      "  File \"/home/smarton/anaconda3/envs/XAI/lib/python3.8/site-packages/IPython/core/interactiveshell.py\", line 2061, in showtraceback\n",
      "    stb = value._render_traceback_()\n",
      "AttributeError: 'TypeError' object has no attribute '_render_traceback_'\n",
      "\n",
      "During handling of the above exception, another exception occurred:\n",
      "\n",
      "Traceback (most recent call last):\n",
      "  File \"/home/smarton/anaconda3/envs/XAI/lib/python3.8/site-packages/IPython/core/ultratb.py\", line 1101, in get_records\n",
      "    return _fixed_getinnerframes(etb, number_of_lines_of_context, tb_offset)\n",
      "  File \"/home/smarton/anaconda3/envs/XAI/lib/python3.8/site-packages/IPython/core/ultratb.py\", line 248, in wrapped\n",
      "    return f(*args, **kwargs)\n",
      "  File \"/home/smarton/anaconda3/envs/XAI/lib/python3.8/site-packages/IPython/core/ultratb.py\", line 281, in _fixed_getinnerframes\n",
      "    records = fix_frame_records_filenames(inspect.getinnerframes(etb, context))\n",
      "  File \"/home/smarton/anaconda3/envs/XAI/lib/python3.8/inspect.py\", line 1503, in getinnerframes\n",
      "    frameinfo = (tb.tb_frame,) + getframeinfo(tb, context)\n",
      "  File \"/home/smarton/anaconda3/envs/XAI/lib/python3.8/inspect.py\", line 1461, in getframeinfo\n",
      "    filename = getsourcefile(frame) or getfile(frame)\n",
      "  File \"/home/smarton/anaconda3/envs/XAI/lib/python3.8/inspect.py\", line 708, in getsourcefile\n",
      "    if getattr(getmodule(object, filename), '__loader__', None) is not None:\n",
      "  File \"/home/smarton/anaconda3/envs/XAI/lib/python3.8/inspect.py\", line 754, in getmodule\n",
      "    os.path.realpath(f)] = module.__name__\n",
      "  File \"/home/smarton/anaconda3/envs/XAI/lib/python3.8/posixpath.py\", line 391, in realpath\n",
      "    path, ok = _joinrealpath(filename[:0], filename, {})\n",
      "  File \"/home/smarton/anaconda3/envs/XAI/lib/python3.8/posixpath.py\", line 425, in _joinrealpath\n",
      "    if not islink(newpath):\n",
      "  File \"/home/smarton/anaconda3/envs/XAI/lib/python3.8/posixpath.py\", line 167, in islink\n",
      "    st = os.lstat(path)\n",
      "KeyboardInterrupt\n"
     ]
    }
   ],
   "source": [
    "if True:\n",
    "    parallel_hpo_synthetic = Parallel(n_jobs=config['computation']['n_jobs'], verbose=3, backend='loky') #loky #sequential multiprocessing\n",
    "    evaluation_results_hpo_synthetic = parallel_hpo_synthetic(delayed(evaluate_parameter_setting_synthetic)(parameter_setting, config, metrics= ['accuracy', 'f1']) for parameter_setting in parameter_grid)\n",
    "\n",
    "    comparator_metric = 'f1'\n",
    "\n",
    "    dhdt_mean_list = [np.mean(evaluation_results_hpo_synthetic[i][0]['DHDT ' + comparator_metric + '_mean']) for i in range(len(parameter_grid))]\n",
    "    dhdt_mean_list = sorted(dhdt_mean_list, reverse=True)\n",
    "\n",
    "    dhdt_max_mean_list = [np.mean(evaluation_results_hpo_synthetic[i][0]['DHDT ' + comparator_metric + '_max']) for i in range(len(parameter_grid))]\n",
    "    dhdt_max_mean_list = [x for _, x in sorted(zip(dhdt_mean_list, dhdt_max_mean_list), reverse=True)]\n",
    "\n",
    "    sklearn_mean_list = [np.mean(evaluation_results_hpo_synthetic[i][0]['sklearn ' + comparator_metric + '_mean']) for i in range(len(parameter_grid))]\n",
    "    sklearn_mean_list = [x for _, x in sorted(zip(dhdt_mean_list, sklearn_mean_list), reverse=True)]\n",
    "\n",
    "    parameter_setting_list = [evaluation_results_hpo_synthetic[i][1] for i in range(len(parameter_grid))]\n",
    "    parameter_setting_list = [x for _, x in sorted(zip(dhdt_mean_list, parameter_setting_list), reverse=True)]\n",
    "\n",
    "    hpo_results_synthetic = []\n",
    "    for i, (dhdt_mean, dhdt_max_mean, sklearn_mean, parameter_setting) in enumerate(zip(dhdt_mean_list, dhdt_max_mean_list, sklearn_mean_list, parameter_setting_list)):\n",
    "        result_dict = {\n",
    "                             'DHDT mean (mean)': dhdt_mean,\n",
    "                             'DHDT max (mean)': dhdt_max_mean,\n",
    "                             'sklearn mean': sklearn_mean,\n",
    "                             'parameters': parameter_setting\n",
    "                            }\n",
    "\n",
    "        hpo_results_synthetic.append(result_dict)\n",
    "\n",
    "    display(hpo_results_synthetic[:5])\n",
    "    \n",
    "    \n",
    "    "
   ]
  },
  {
   "cell_type": "code",
   "execution_count": 9,
   "id": "7af8512c-cb73-43ac-811a-d7d334db97ee",
   "metadata": {
    "execution": {
     "iopub.execute_input": "2022-06-10T10:43:55.044459Z",
     "iopub.status.busy": "2022-06-10T10:43:55.044325Z",
     "iopub.status.idle": "2022-06-10T10:43:55.052745Z",
     "shell.execute_reply": "2022-06-10T10:43:55.052234Z",
     "shell.execute_reply.started": "2022-06-10T10:43:55.044440Z"
    },
    "tags": []
   },
   "outputs": [],
   "source": [
    "if False:\n",
    "    identifier_list = [\n",
    "                        'Adult',#: 32,\n",
    "                        'Bank Marketing',#: 32,\n",
    "                        'Loan Credit',#: 32,\n",
    "\n",
    "                        'Credit Card',#: 23, \n",
    "                        'Car',#: 21,\n",
    "\n",
    "\n",
    "                        'Absenteeism',#: 15,\n",
    "                        'Loan House',#: 15,\n",
    "                        'Cervical Cancer',#: 15,\n",
    "\n",
    "                        'Heart Disease',#: 13,           \n",
    "\n",
    "                        'Titanic',#: 10,\n",
    "                        'Medical Insurance',#: 10,\n",
    "                        'Wisconsin Breast Cancer Original',#: 10,\n",
    "                        'Wisconsin Diagnostic Breast Cancer',#: 10,\n",
    "                        'Wisconsin Prognostic Breast Cancer',#: 10,\n",
    "                        'Abalone',#: 10,\n",
    "\n",
    "                        'Habermans Survival',#: 3, \n",
    "                      ]\n",
    "\n",
    "    hpo_results_real_world = {}\n",
    "\n",
    "    for identifier in identifier_list:\n",
    "        parallel_hpo_real = Parallel(n_jobs=config['computation']['n_jobs'], verbose=3, backend='loky') #loky #sequential multiprocessing\n",
    "        evaluation_results_hpo_real = parallel_hpo_real(delayed(evaluate_parameter_setting_real_world)(parameter_setting, identifier, config, metrics= ['accuracy', 'f1']) for parameter_setting in parameter_grid)\n",
    "\n",
    "        comparator_metric = 'f1'\n",
    "\n",
    "        dhdt_mean_list = [np.mean(evaluation_results_hpo_real[i][0]['DHDT ' + comparator_metric + '_mean']) for i in range(len(parameter_grid))]\n",
    "        dhdt_mean_list = sorted(dhdt_mean_list, reverse=True)\n",
    "\n",
    "        dhdt_max_mean_list = [np.mean(evaluation_results_hpo_real[i][0]['DHDT ' + comparator_metric + '_max']) for i in range(len(parameter_grid))]\n",
    "        dhdt_max_mean_list = [x for _, x in sorted(zip(dhdt_mean_list, dhdt_max_mean_list), reverse=True)]\n",
    "\n",
    "        sklearn_mean_list = [np.mean(evaluation_results_hpo_real[i][0]['sklearn ' + comparator_metric + '_mean']) for i in range(len(parameter_grid))]\n",
    "        sklearn_mean_list = [x for _, x in sorted(zip(dhdt_mean_list, sklearn_mean_list), reverse=True)]\n",
    "\n",
    "        parameter_setting_list = [evaluation_results_hpo_real[i][1] for i in range(len(parameter_grid))]\n",
    "        parameter_setting_list = [x for _, x in sorted(zip(dhdt_mean_list, parameter_setting_list), reverse=True)]\n",
    "\n",
    "        hpo_results_real_world_by_identifer = []\n",
    "        for i, (dhdt_mean, dhdt_max_mean, sklearn_mean, parameter_setting) in enumerate(zip(dhdt_mean_list, dhdt_max_mean_list, sklearn_mean_list, parameter_setting_list)):\n",
    "            result_dict = {\n",
    "                                 'DHDT mean (mean)': dhdt_mean,\n",
    "                                 'DHDT max (mean)': dhdt_max_mean,\n",
    "                                 'sklearn mean': sklearn_mean,\n",
    "                                 'parameters': parameter_setting\n",
    "                                }\n",
    "\n",
    "            hpo_results_real_world_by_identifer.append(result_dict)\n",
    "\n",
    "        hpo_results_real_world[identifier] = hpo_results_real_world_by_identifer\n",
    "\n",
    "        display(hpo_results_real_world_by_identifer[:5])\n",
    "        "
   ]
  },
  {
   "cell_type": "code",
   "execution_count": null,
   "id": "40147db1-760f-432d-ac2c-0267a8256f8a",
   "metadata": {},
   "outputs": [],
   "source": []
  },
  {
   "cell_type": "code",
   "execution_count": null,
   "id": "9358c9e7-58be-4006-b120-6b14f8364122",
   "metadata": {},
   "outputs": [],
   "source": []
  },
  {
   "cell_type": "code",
   "execution_count": null,
   "id": "2eb18776-1d0a-4ec1-a109-7c55b8acbe27",
   "metadata": {},
   "outputs": [],
   "source": []
  }
 ],
 "metadata": {
  "kernelspec": {
   "display_name": "Python 3 (ipykernel)",
   "language": "python",
   "name": "python3"
  },
  "language_info": {
   "codemirror_mode": {
    "name": "ipython",
    "version": 3
   },
   "file_extension": ".py",
   "mimetype": "text/x-python",
   "name": "python",
   "nbconvert_exporter": "python",
   "pygments_lexer": "ipython3",
   "version": "3.8.0"
  }
 },
 "nbformat": 4,
 "nbformat_minor": 5
}
